Workbook

Sheet Task Tracker
A1: 🏭 PET FACTORY MAROC — Scope of Work Project Tracker
A2: # | B2: System | C2: Spec | D2: Phase / Task | E2: Sub-Task | F2: Owner | G2: Status | H2: Start | I2: End | J2: Weeks | K2: Notes
A3: SYSTEM 1 · Boiler System (6000 Kg/H)
A4: 1 | B4: Boiler System | C4: 6000 Kg/H | D4: Design & Engineering | E4: Technical Specs Review | F4: Engineering | G4: Complete | H4: 46133 | I4: 46146 | J4: =IF(AND(H4<>"",I4<>""),IF(I4>=H4,ROUNDUP((I4-H4+1)/7,0),""),"") -> 2 | K4: Verify steam output vs production demand
A5: 1 | B5: Boiler System | C5: 6000 Kg/H | D5: Design & Engineering | E5: P&ID Drawing Approval | F5: Engineering | G5: Complete | H5: 46140 | I5: 46153 | J5: =IF(AND(H5<>"",I5<>""),IF(I5>=H5,ROUNDUP((I5-H5+1)/7,0),""),"") -> 2 | K5: FAMSUN to submit by May 31
A6: 1 | B6: Boiler System | C6: 6000 Kg/H | D6: Procurement | E6: Vendor Finalization | F6: Procurement | G6: In Progress | H6: 46153 | I6: 46214 | J6: =IF(AND(H6<>"",I6<>""),IF(I6>=H6,ROUNDUP((I6-H6+1)/7,0),""),"") -> 9
A7: 1 | B7: Boiler System | C7: 6000 Kg/H | D7: Procurement | E7: Purchase Order Issued | F7: Procurement | G7: Not Started | H7: 46214 | I7: 46221 | J7: =IF(AND(H7<>"",I7<>""),IF(I7>=H7,ROUNDUP((I7-H7+1)/7,0),""),"") -> 2
A8: 1 | B8: Boiler System | C8: 6000 Kg/H | D8: Procurement | E8: Manufacturing & QC | F8: Supplier | G8: Not Started | H8: 46221 | I8: 46252 | J8: =IF(AND(H8<>"",I8<>""),IF(I8>=H8,ROUNDUP((I8-H8+1)/7,0),""),"") -> 5 | K8: Factory inspection at week 7
A9: 1 | B9: Boiler System | C9: 6000 Kg/H | D9: Delivery & Logistics | E9: Shipping / Sea Freight | F9: Logistics | G9: Not Started | H9: 46252 | I9: 46283 | J9: =IF(AND(H9<>"",I9<>""),IF(I9>=H9,ROUNDUP((I9-H9+1)/7,0),""),"") -> 5
A10: 1 | B10: Boiler System | C10: 6000 Kg/H | D10: Delivery & Logistics | E10: Customs Clearance | F10: Logistics | G10: Not Started | H10: 46283 | I10: 46313 | J10: =IF(AND(H10<>"",I10<>""),IF(I10>=H10,ROUNDUP((I10-H10+1)/7,0),""),"") -> 5
A11: 1 | B11: Boiler System | C11: 6000 Kg/H | D11: Delivery & Logistics | E11: Site Delivery | F11: Logistics | G11: Not Started | H11: 46313 | I11: 46323 | J11: =IF(AND(H11<>"",I11<>""),IF(I11>=H11,ROUNDUP((I11-H11+1)/7,0),""),"") -> 2
A12: 1 | B12: Boiler System | C12: 6000 Kg/H | D12: Installation | E12: Civil & Foundation Prep | F12: Civil Contractor | G12: Not Started | H12: 46191 | I12: 46236 | J12: =IF(AND(H12<>"",I12<>""),IF(I12>=H12,ROUNDUP((I12-H12+1)/7,0),""),"") -> 7
A13: 1 | B13: Boiler System | C13: 6000 Kg/H | D13: Installation | E13: Equipment Installation | F13: Install Team | G13: Not Started | H13: 46323 | I13: 46334 | J13: =IF(AND(H13<>"",I13<>""),IF(I13>=H13,ROUNDUP((I13-H13+1)/7,0),""),"") -> 2
A14: 1 | B14: Boiler System | C14: 6000 Kg/H | D14: Installation | E14: Piping & Connections | F14: Install Team | G14: Not Started | H14: 46217 | I14: 46248 | J14: =IF(AND(H14<>"",I14<>""),IF(I14>=H14,ROUNDUP((I14-H14+1)/7,0),""),"") -> 5
A15: 1 | B15: Boiler System | C15: 6000 Kg/H | D15: Testing & Commissioning | E15: Factory Acceptance Test | F15: Engineering | G15: Not Started | H15: 46334 | I15: 46344 | J15: =IF(AND(H15<>"",I15<>""),IF(I15>=H15,ROUNDUP((I15-H15+1)/7,0),""),"") -> 2 | K15: At supplier factory
A16: 1 | B16: Boiler System | C16: 6000 Kg/H | D16: Testing & Commissioning | E16: Site Acceptance Test | F16: Engineering | G16: Not Started | H16: 46344 | I16: 46350 | J16: =IF(AND(H16<>"",I16<>""),IF(I16>=H16,ROUNDUP((I16-H16+1)/7,0),""),"") -> 1
A17: 1 | B17: Boiler System | C17: 6000 Kg/H | D17: Testing & Commissioning | E17: Performance Verification | F17: Engineering | G17: Not Started | H17: 46344 | I17: 46350 | J17: =IF(AND(H17<>"",I17<>""),IF(I17>=H17,ROUNDUP((I17-H17+1)/7,0),""),"") -> 1 | K17: Confirm 6000 Kg/H output
A18: SYSTEM 2 · Air Compressor System (37 kW ×2)
A19: 2 | B19: Air Compressor System | C19: 37 kW ×2 | D19: Design & Engineering | E19: Compressed Air Demand Audit | F19: Engineering | G19: Complete | H19: 46133 | I19: 46146 | J19: =IF(AND(H19<>"",I19<>""),IF(I19>=H19,ROUNDUP((I19-H19+1)/7,0),""),"") -> 2
A20: 2 | B20: Air Compressor System | C20: 37 kW ×2 | D20: Design & Engineering | E20: Piping Layout Approval | F20: Engineering | G20: Complete | H20: 46140 | I20: 46153 | J20: =IF(AND(H20<>"",I20<>""),IF(I20>=H20,ROUNDUP((I20-H20+1)/7,0),""),"") -> 2
A21: 2 | B21: Air Compressor System | C21: 37 kW ×2 | D21: Procurement | E21: Vendor Finalization | F21: Procurement | G21: In Progress | H21: 46153 | I21: 46214 | J21: =IF(AND(H21<>"",I21<>""),IF(I21>=H21,ROUNDUP((I21-H21+1)/7,0),""),"") -> 9
A22: 2 | B22: Air Compressor System | C22: 37 kW ×2 | D22: Procurement | E22: Purchase Order Issued | F22: Procurement | G22: Not Started | H22: 46214 | I22: 46221 | J22: =IF(AND(H22<>"",I22<>""),IF(I22>=H22,ROUNDUP((I22-H22+1)/7,0),""),"") -> 2
A23: 2 | B23: Air Compressor System | C23: 37 kW ×2 | D23: Procurement | E23: Manufacturing & QC | F23: Supplier | G23: Not Started | H23: 46221 | I23: 46252 | J23: =IF(AND(H23<>"",I23<>""),IF(I23>=H23,ROUNDUP((I23-H23+1)/7,0),""),"") -> 5
A24: 2 | B24: Air Compressor System | C24: 37 kW ×2 | D24: Delivery & Logistics | E24: Shipping | F24: Logistics | G24: Not Started | H24: 46252 | I24: 46283 | J24: =IF(AND(H24<>"",I24<>""),IF(I24>=H24,ROUNDUP((I24-H24+1)/7,0),""),"") -> 5
A25: 2 | B25: Air Compressor System | C25: 37 kW ×2 | D25: Delivery & Logistics | E25: Customs Clearance | F25: Logistics | G25: Not Started | H25: 46283 | I25: 46313 | J25: =IF(AND(H25<>"",I25<>""),IF(I25>=H25,ROUNDUP((I25-H25+1)/7,0),""),"") -> 5
A26: 2 | B26: Air Compressor System | C26: 37 kW ×2 | D26: Delivery & Logistics | E26: Site Delivery | F26: Logistics | G26: Not Started | H26: 46313 | I26: 46323 | J26: =IF(AND(H26<>"",I26<>""),IF(I26>=H26,ROUNDUP((I26-H26+1)/7,0),""),"") -> 2
A27: 2 | B27: Air Compressor System | C27: 37 kW ×2 | D27: Installation | E27: Compressor Room Preparation | F27: Civil Contractor | G27: Not Started | H27: 46191 | I27: 46236 | J27: =IF(AND(H27<>"",I27<>""),IF(I27>=H27,ROUNDUP((I27-H27+1)/7,0),""),"") -> 7 | K27: Ventilation & cooling req.
A28: 2 | B28: Air Compressor System | C28: 37 kW ×2 | D28: Installation | E28: Equipment Installation | F28: Install Team | G28: Not Started | H28: 46323 | I28: 46334 | J28: =IF(AND(H28<>"",I28<>""),IF(I28>=H28,ROUNDUP((I28-H28+1)/7,0),""),"") -> 2
A29: 2 | B29: Air Compressor System | C29: 37 kW ×2 | D29: Installation | E29: Pipe Network Connection | F29: Install Team | G29: Not Started | H29: 46217 | I29: 46248 | J29: =IF(AND(H29<>"",I29<>""),IF(I29>=H29,ROUNDUP((I29-H29+1)/7,0),""),"") -> 5
A30: 2 | B30: Air Compressor System | C30: 37 kW ×2 | D30: Testing & Commissioning | E30: Pressure & Leak Test | F30: Engineering | G30: Not Started | H30: 46334 | I30: 46344 | J30: =IF(AND(H30<>"",I30<>""),IF(I30>=H30,ROUNDUP((I30-H30+1)/7,0),""),"") -> 2
A31: 2 | B31: Air Compressor System | C31: 37 kW ×2 | D31: Testing & Commissioning | E31: Performance Verification | F31: Engineering | G31: Not Started | H31: 46344 | I31: 46350 | J31: =IF(AND(H31<>"",I31<>""),IF(I31>=H31,ROUNDUP((I31-H31+1)/7,0),""),"") -> 1 | K31: Confirm 4.3 m³/H
A32: SYSTEM 3 · Water System (10000 Kg/H)
A33: 3 | B33: Water System | C33: 10000 Kg/H | D33: Design & Engineering | E33: Water Balance Study | F33: Engineering | G33: Complete | H33: 46140 | I33: 46153 | J33: =IF(AND(H33<>"",I33<>""),IF(I33>=H33,ROUNDUP((I33-H33+1)/7,0),""),"") -> 2
A34: 3 | B34: Water System | C34: 10000 Kg/H | D34: Design & Engineering | E34: Plumbing Drawing Approval | F34: Engineering | G34: Complete | H34: 46153 | I34: 46214 | J34: =IF(AND(H34<>"",I34<>""),IF(I34>=H34,ROUNDUP((I34-H34+1)/7,0),""),"") -> 9
A35: 3 | B35: Water System | C35: 10000 Kg/H | D35: Procurement | E35: Pump & Tank Selection | F35: Procurement | G35: In Progress | H35: 46214 | I35: 46221 | J35: =IF(AND(H35<>"",I35<>""),IF(I35>=H35,ROUNDUP((I35-H35+1)/7,0),""),"") -> 2
A36: 3 | B36: Water System | C36: 10000 Kg/H | D36: Procurement | E36: Purchase Order Issued | F36: Procurement | G36: Not Started | H36: 46221 | I36: 46252 | J36: =IF(AND(H36<>"",I36<>""),IF(I36>=H36,ROUNDUP((I36-H36+1)/7,0),""),"") -> 5
A37: 3 | B37: Water System | C37: 10000 Kg/H | D37: Procurement | E37: Manufacturing / Supply | F37: Supplier | G37: Not Started | H37: 46252 | I37: 46283 | J37: =IF(AND(H37<>"",I37<>""),IF(I37>=H37,ROUNDUP((I37-H37+1)/7,0),""),"") -> 5
A38: 3 | B38: Water System | C38: 10000 Kg/H | D38: Delivery & Logistics | E38: Shipping | F38: Logistics | G38: Not Started | H38: 46283 | I38: 46313 | J38: =IF(AND(H38<>"",I38<>""),IF(I38>=H38,ROUNDUP((I38-H38+1)/7,0),""),"") -> 5
A39: 3 | B39: Water System | C39: 10000 Kg/H | D39: Delivery & Logistics | E39: Site Delivery | F39: Logistics | G39: Not Started | H39: 46313 | I39: 46323 | J39: =IF(AND(H39<>"",I39<>""),IF(I39>=H39,ROUNDUP((I39-H39+1)/7,0),""),"") -> 2
A40: 3 | B40: Water System | C40: 10000 Kg/H | D40: Installation | E40: Trenching & Civil Works | F40: Civil Contractor | G40: Not Started | H40: 46191 | I40: 46236 | J40: =IF(AND(H40<>"",I40<>""),IF(I40>=H40,ROUNDUP((I40-H40+1)/7,0),""),"") -> 7
...

Sheet Dashboard
A1: 📊 PET FACTORY MAROC — Project Dashboard
A3: Key Metrics
A4: Total Tasks | C4: Complete | E4: In Progress | G4: Not Started
A5: =COUNT('Task Tracker'!$A$4:$A$144) -> 128 | C5: =COUNTIF('Task Tracker'!$G$4:$G$144,"Complete") -> 24 | E5: =COUNTIF('Task Tracker'!$G$4:$G$144,"In Progress") -> 14 | G5: =COUNTIF('Task Tracker'!$G$4:$G$144,"Not Started") -> 90
A7: Overall Completion (weighted: Complete=100%, In Progress=50%)
A8: Project % | C8: =(COUNTIF('Task Tracker'!$G$4:$G$144,"Complete")+0.5*COUNTIF('Task Tracker'!$G$4:$G$144,"In Progress"))/COUNT('Task Tracker'!$A$4:$A$144) -> 0.2421875
A9: System Summary
A10: # | B10: System | C10: Spec | D10: Total | E10: Not Started | F10: In Progress | G10: Complete | H10: % Complete
A11: 1 | B11: Boiler System | C11: 6000 Kg/H | D11: =COUNTIF('Task Tracker'!$A$4:$A$144,1) -> 14 | E11: =COUNTIFS('Task Tracker'!$A$4:$A$144,1,'Task Tracker'!$G$4:$G$144,"Not Started") -> 11 | F11: =COUNTIFS('Task Tracker'!$A$4:$A$144,1,'Task Tracker'!$G$4:$G$144,"In Progress") -> 1 | G11: =COUNTIFS('Task Tracker'!$A$4:$A$144,1,'Task Tracker'!$G$4:$G$144,"Complete") -> 2 | H11: =IFERROR((G11+0.5*F11)/D11,0) -> 0.17857143
A12: 2 | B12: Air Compressor System | C12: 37 kW ×2 | D12: =COUNTIF('Task Tracker'!$A$4:$A$144,2) -> 13 | E12: =COUNTIFS('Task Tracker'!$A$4:$A$144,2,'Task Tracker'!$G$4:$G$144,"Not Started") -> 10 | F12: =COUNTIFS('Task Tracker'!$A$4:$A$144,2,'Task Tracker'!$G$4:$G$144,"In Progress") -> 1 | G12: =COUNTIFS('Task Tracker'!$A$4:$A$144,2,'Task Tracker'!$G$4:$G$144,"Complete") -> 2 | H12: =IFERROR((G12+0.5*F12)/D12,0) -> 0.19230769
A13: 3 | B13: Water System | C13: 10000 Kg/H | D13: =COUNTIF('Task Tracker'!$A$4:$A$144,3) -> 12 | E13: =COUNTIFS('Task Tracker'!$A$4:$A$144,3,'Task Tracker'!$G$4:$G$144,"Not Started") -> 9 | F13: =COUNTIFS('Task Tracker'!$A$4:$A$144,3,'Task Tracker'!$G$4:$G$144,"In Progress") -> 1 | G13: =COUNTIFS('Task Tracker'!$A$4:$A$144,3,'Task Tracker'!$G$4:$G$144,"Complete") -> 2 | H13: =IFERROR((G13+0.5*F13)/D13,0) -> 0.20833333
A14: 4 | B14: Weighbridge | C14: 60T | D14: =COUNTIF('Task Tracker'!$A$4:$A$144,4) -> 10 | E14: =COUNTIFS('Task Tracker'!$A$4:$A$144,4,'Task Tracker'!$G$4:$G$144,"Not Started") -> 7 | F14: =COUNTIFS('Task Tracker'!$A$4:$A$144,4,'Task Tracker'!$G$4:$G$144,"In Progress") -> 1 | G14: =COUNTIFS('Task Tracker'!$A$4:$A$144,4,'Task Tracker'!$G$4:$G$144,"Complete") -> 2 | H14: =IFERROR((G14+0.5*F14)/D14,0) -> 0.25
A15: 5 | B15: Big Storage Oil Tank | C15: 2 × 20,000 L | D15: =COUNTIF('Task Tracker'!$A$4:$A$144,5) -> 12 | E15: =COUNTIFS('Task Tracker'!$A$4:$A$144,5,'Task Tracker'!$G$4:$G$144,"Not Started") -> 11 | F15: =COUNTIFS('Task Tracker'!$A$4:$A$144,5,'Task Tracker'!$G$4:$G$144,"In Progress") -> 1 | G15: =COUNTIFS('Task Tracker'!$A$4:$A$144,5,'Task Tracker'!$G$4:$G$144,"Complete") -> 0 | H15: =IFERROR((G15+0.5*F15)/D15,0) -> 0.041666667
A16: 6 | B16: Elevator | C16: 2×2T | D16: =COUNTIF('Task Tracker'!$A$4:$A$144,6) -> 14 | E16: =COUNTIFS('Task Tracker'!$A$4:$A$144,6,'Task Tracker'!$G$4:$G$144,"Not Started") -> 11 | F16: =COUNTIFS('Task Tracker'!$A$4:$A$144,6,'Task Tracker'!$G$4:$G$144,"In Progress") -> 1 | G16: =COUNTIFS('Task Tracker'!$A$4:$A$144,6,'Task Tracker'!$G$4:$G$144,"Complete") -> 2 | H16: =IFERROR((G16+0.5*F16)/D16,0) -> 0.17857143
A17: 7 | B17: Electrical Installation & Transformer | C17: 1600 KVA | D17: =COUNTIF('Task Tracker'!$A$4:$A$144,7) -> 12 | E17: =COUNTIFS('Task Tracker'!$A$4:$A$144,7,'Task Tracker'!$G$4:$G$144,"Not Started") -> 8 | F17: =COUNTIFS('Task Tracker'!$A$4:$A$144,7,'Task Tracker'!$G$4:$G$144,"In Progress") -> 0 | G17: =COUNTIFS('Task Tracker'!$A$4:$A$144,7,'Task Tracker'!$G$4:$G$144,"Complete") -> 4 | H17: =IFERROR((G17+0.5*F17)/D17,0) -> 0.33333333
A18: 8 | B18: Aménagement Extérieur | C18: Béton | D18: =COUNTIF('Task Tracker'!$A$4:$A$144,8) -> 3 | E18: =COUNTIFS('Task Tracker'!$A$4:$A$144,8,'Task Tracker'!$G$4:$G$144,"Not Started") -> 0 | F18: =COUNTIFS('Task Tracker'!$A$4:$A$144,8,'Task Tracker'!$G$4:$G$144,"In Progress") -> 1 | G18: =COUNTIFS('Task Tracker'!$A$4:$A$144,8,'Task Tracker'!$G$4:$G$144,"Complete") -> 2 | H18: =IFERROR((G18+0.5*F18)/D18,0) -> 0.83333333
A19: 9 | B19: Solaire Électricité | C19: 30% × 1600 KVA | D19: =COUNTIF('Task Tracker'!$A$4:$A$144,9) -> 14 | E19: =COUNTIFS('Task Tracker'!$A$4:$A$144,9,'Task Tracker'!$G$4:$G$144,"Not Started") -> 14 | F19: =COUNTIFS('Task Tracker'!$A$4:$A$144,9,'Task Tracker'!$G$4:$G$144,"In Progress") -> 0 | G19: =COUNTIFS('Task Tracker'!$A$4:$A$144,9,'Task Tracker'!$G$4:$G$144,"Complete") -> 0 | H19: =IFERROR((G19+0.5*F19)/D19,0) -> 0
A20: 10 | B20: Installation GAZ | C20: 15 m³ | D20: =COUNTIF('Task Tracker'!$A$4:$A$144,10) -> 12 | E20: =COUNTIFS('Task Tracker'!$A$4:$A$144,10,'Task Tracker'!$G$4:$G$144,"Not Started") -> 9 | F20: =COUNTIFS('Task Tracker'!$A$4:$A$144,10,'Task Tracker'!$G$4:$G$144,"In Progress") -> 1 | G20: =COUNTIFS('Task Tracker'!$A$4:$A$144,10,'Task Tracker'!$G$4:$G$144,"Complete") -> 2 | H20: =IFERROR((G20+0.5*F20)/D20,0) -> 0.20833333
A21: 11 | B21: Séparation et Froid Industriel | C21: Dry | D21: =COUNTIF('Task Tracker'!$A$4:$A$144,11) -> 3 | E21: =COUNTIFS('Task Tracker'!$A$4:$A$144,11,'Task Tracker'!$G$4:$G$144,"Not Started") -> 0 | F21: =COUNTIFS('Task Tracker'!$A$4:$A$144,11,'Task Tracker'!$G$4:$G$144,"In Progress") -> 2 | G21: =COUNTIFS('Task Tracker'!$A$4:$A$144,11,'Task Tracker'!$G$4:$G$144,"Complete") -> 1 | H21: =IFERROR((G21+0.5*F21)/D21,0) -> 0.66666667
A22: 12 | B22: Séparation Salle de Commande & MCC | C22: Dry | D22: =COUNTIF('Task Tracker'!$A$4:$A$144,12) -> 3 | E22: =COUNTIFS('Task Tracker'!$A$4:$A$144,12,'Task Tracker'!$G$4:$G$144,"Not Started") -> 0 | F22: =COUNTIFS('Task Tracker'!$A$4:$A$144,12,'Task Tracker'!$G$4:$G$144,"In Progress") -> 1 | G22: =COUNTIFS('Task Tracker'!$A$4:$A$144,12,'Task Tracker'!$G$4:$G$144,"Complete") -> 2 | H22: =IFERROR((G22+0.5*F22)/D22,0) -> 0.83333333
A23: 13 | B23: Recrutement | D23: =COUNTIF('Task Tracker'!$A$4:$A$144,13) -> 3 | E23: =COUNTIFS('Task Tracker'!$A$4:$A$144,13,'Task Tracker'!$G$4:$G$144,"Not Started") -> 0 | F23: =COUNTIFS('Task Tracker'!$A$4:$A$144,13,'Task Tracker'!$G$4:$G$144,"In Progress") -> 1 | G23: =COUNTIFS('Task Tracker'!$A$4:$A$144,13,'Task Tracker'!$G$4:$G$144,"Complete") -> 2 | H23: =IFERROR((G23+0.5*F23)/D23,0) -> 0.83333333
A24: 14 | B24: Logiciel | D24: =COUNTIF('Task Tracker'!$A$4:$A$144,14) -> 3 | E24: =COUNTIFS('Task Tracker'!$A$4:$A$144,14,'Task Tracker'!$G$4:$G$144,"Not Started") -> 0 | F24: =COUNTIFS('Task Tracker'!$A$4:$A$144,14,'Task Tracker'!$G$4:$G$144,"In Progress") -> 2 | G24: =COUNTIFS('Task Tracker'!$A$4:$A$144,14,'Task Tracker'!$G$4:$G$144,"Complete") -> 1 | H24: =IFERROR((G24+0.5*F24)/D24,0) -> 0.66666667
B25: TOTAL | D25: =SUM(D11:D24) -> 128 | E25: =SUM(E11:E24) -> 90 | F25: =SUM(F11:F24) -> 14 | G25: =SUM(G11:G24) -> 24 | H25: =IFERROR((G25+0.5*F25)/D25,0) -> 0.2421875
A27: Key Project Milestones
A28: Date | C28: Milestone | H28: Status
A29: 46173 | C29: FAMSUN Drawing Review Deadline (Boiler + Elevator) | H29: Complete
A30: 46214 | C30: Boiler / Compressor / Elevator Vendor Finalization | H30: In Progress
A31: 46252 | C31: Boiler & Elevator Manufacturing Complete | H31: Not Started
A32: 46283 | C32: Major Equipment Shipping Complete | H32: Not Started
A33: 46323 | C33: Site Deliveries Complete | H33: Not Started
A34: 46334 | C34: Equipment Installation Complete | H34: Not Started
A35: 46350 | C35: All Systems Tested & Commissioned — Facility Ready | H35: Not Started
A37: As of: | C37: =TODAY() -> 46196

Sheet Gantt Chart
A1: 📅 PET FACTORY MAROC — Dynamic Project Gantt (bars update automatically from Task Tracker dates & status)
A2: # | B2: System | C2: Sub-Task | D2: Status | E2: Start | F2: End | G2: 46133 | H2: 46140 | I2: 46147 | J2: 46154 | K2: 46161 | L2: 46168 | M2: 46175 | N2: 46182 | O2: 46189 | P2: 46196 | Q2: 46203 | R2: 46210 | S2: 46217 | T2: 46224 | U2: 46231 | V2: 46238 | W2: 46245 | X2: 46252 | Y2: 46259 | Z2: 46266 | AA2: 46273 | AB2: 46280 | AC2: 46287 | AD2: 46294 | AE2: 46301 | AF2: 46308 | AG2: 46315 | AH2: 46322 | AI2: 46329 | AJ2: 46336 | AK2: 46343 | AL2: 46350
A3: ▶ SYSTEM 1 — Boiler System (6000 Kg/H)
A4: ='Task Tracker'!A4 -> 1 | B4: ='Task Tracker'!B4 -> Boiler System | C4: ='Task Tracker'!E4 -> Technical Specs Review | D4: ='Task Tracker'!G4 -> Complete | E4: ='Task Tracker'!H4 -> 46133 | F4: ='Task Tracker'!I4 -> 46146
A5: ='Task Tracker'!A5 -> 1 | B5: ='Task Tracker'!B5 -> Boiler System | C5: ='Task Tracker'!E5 -> P&ID Drawing Approval | D5: ='Task Tracker'!G5 -> Complete | E5: ='Task Tracker'!H5 -> 46140 | F5: ='Task Tracker'!I5 -> 46153
A6: ='Task Tracker'!A6 -> 1 | B6: ='Task Tracker'!B6 -> Boiler System | C6: ='Task Tracker'!E6 -> Vendor Finalization | D6: ='Task Tracker'!G6 -> In Progress | E6: ='Task Tracker'!H6 -> 46153 | F6: ='Task Tracker'!I6 -> 46214
A7: ='Task Tracker'!A7 -> 1 | B7: ='Task Tracker'!B7 -> Boiler System | C7: ='Task Tracker'!E7 -> Purchase Order Issued | D7: ='Task Tracker'!G7 -> Not Started | E7: ='Task Tracker'!H7 -> 46214 | F7: ='Task Tracker'!I7 -> 46221
A8: ='Task Tracker'!A8 -> 1 | B8: ='Task Tracker'!B8 -> Boiler System | C8: ='Task Tracker'!E8 -> Manufacturing & QC | D8: ='Task Tracker'!G8 -> Not Started | E8: ='Task Tracker'!H8 -> 46221 | F8: ='Task Tracker'!I8 -> 46252
A9: ='Task Tracker'!A9 -> 1 | B9: ='Task Tracker'!B9 -> Boiler System | C9: ='Task Tracker'!E9 -> Shipping / Sea Freight | D9: ='Task Tracker'!G9 -> Not Started | E9: ='Task Tracker'!H9 -> 46252 | F9: ='Task Tracker'!I9 -> 46283
A10: ='Task Tracker'!A10 -> 1 | B10: ='Task Tracker'!B10 -> Boiler System | C10: ='Task Tracker'!E10 -> Customs Clearance | D10: ='Task Tracker'!G10 -> Not Started | E10: ='Task Tracker'!H10 -> 46283 | F10: ='Task Tracker'!I10 -> 46313
A11: ='Task Tracker'!A11 -> 1 | B11: ='Task Tracker'!B11 -> Boiler System | C11: ='Task Tracker'!E11 -> Site Delivery | D11: ='Task Tracker'!G11 -> Not Started | E11: ='Task Tracker'!H11 -> 46313 | F11: ='Task Tracker'!I11 -> 46323
A12: ='Task Tracker'!A12 -> 1 | B12: ='Task Tracker'!B12 -> Boiler System | C12: ='Task Tracker'!E12 -> Civil & Foundation Prep | D12: ='Task Tracker'!G12 -> Not Started | E12: ='Task Tracker'!H12 -> 46191 | F12: ='Task Tracker'!I12 -> 46236
A13: ='Task Tracker'!A13 -> 1 | B13: ='Task Tracker'!B13 -> Boiler System | C13: ='Task Tracker'!E13 -> Equipment Installation | D13: ='Task Tracker'!G13 -> Not Started | E13: ='Task Tracker'!H13 -> 46323 | F13: ='Task Tracker'!I13 -> 46334
A14: ='Task Tracker'!A14 -> 1 | B14: ='Task Tracker'!B14 -> Boiler System | C14: ='Task Tracker'!E14 -> Piping & Connections | D14: ='Task Tracker'!G14 -> Not Started | E14: ='Task Tracker'!H14 -> 46217 | F14: ='Task Tracker'!I14 -> 46248
A15: ='Task Tracker'!A15 -> 1 | B15: ='Task Tracker'!B15 -> Boiler System | C15: ='Task Tracker'!E15 -> Factory Acceptance Test | D15: ='Task Tracker'!G15 -> Not Started | E15: ='Task Tracker'!H15 -> 46334 | F15: ='Task Tracker'!I15 -> 46344
... A17: ='Task Tracker'!A17 -> 1 | B17: ='Task Tracker'!B17 -> Boiler System | C17: ='Task Tracker'!E17 -> Performance Verification | D17: ='Task Tracker'!G17 -> Not Started | E17: ='Task Tracker'!H17 -> 46344 | F17: ='Task Tracker'!I17 -> 46350
A18: ▶ SYSTEM 2 — Air Compressor System (37 kW ×2)
A19: ='Task Tracker'!A19 -> 2 | B19: ='Task Tracker'!B19 -> Air Compressor System | C19: ='Task Tracker'!E19 -> Compressed Air Demand Audit | D19: ='Task Tracker'!G19 -> Complete | E19: ='Task Tracker'!H19 -> 46133 | F19: ='Task Tracker'!I19 -> 46146
A20: ='Task Tracker'!A20 -> 2 | B20: ='Task Tracker'!B20 -> Air Compressor System | C20: ='Task Tracker'!E20 -> Piping Layout Approval | D20: ='Task Tracker'!G20 -> Complete | E20: ='Task Tracker'!H20 -> 46140 | F20: ='Task Tracker'!I20 -> 46153
A21: ='Task Tracker'!A21 -> 2 | B21: ='Task Tracker'!B21 -> Air Compressor System | C21: ='Task Tracker'!E21 -> Vendor Finalization | D21: ='Task Tracker'!G21 -> In Progress | E21: ='Task Tracker'!H21 -> 46153 | F21: ='Task Tracker'!I21 -> 46214
A22: ='Task Tracker'!A22 -> 2 | B22: ='Task Tracker'!B22 -> Air Compressor System | C22: ='Task Tracker'!E22 -> Purchase Order Issued | D22: ='Task Tracker'!G22 -> Not Started | E22: ='Task Tracker'!H22 -> 46214 | F22: ='Task Tracker'!I22 -> 46221
A23: ='Task Tracker'!A23 -> 2 | B23: ='Task Tracker'!B23 -> Air Compressor System | C23: ='Task Tracker'!E23 -> Manufacturing & QC | D23: ='Task Tracker'!G23 -> Not Started | E23: ='Task Tracker'!H23 -> 46221 | F23: ='Task Tracker'!I23 -> 46252
A24: ='Task Tracker'!A24 -> 2 | B24: ='Task Tracker'!B24 -> Air Compressor System | C24: ='Task Tracker'!E24 -> Shipping | D24: ='Task Tracker'!G24 -> Not Started | E24: ='Task Tracker'!H24 -> 46252 | F24: ='Task Tracker'!I24 -> 46283
A25: ='Task Tracker'!A25 -> 2 | B25: ='Task Tracker'!B25 -> Air Compressor System | C25: ='Task Tracker'!E25 -> Customs Clearance | D25: ='Task Tracker'!G25 -> Not Started | E25: ='Task Tracker'!H25 -> 46283 | F25: ='Task Tracker'!I25 -> 46313
A26: ='Task Tracker'!A26 -> 2 | B26: ='Task Tracker'!B26 -> Air Compressor System | C26: ='Task Tracker'!E26 -> Site Delivery | D26: ='Task Tracker'!G26 -> Not Started | E26: ='Task Tracker'!H26 -> 46313 | F26: ='Task Tracker'!I26 -> 46323
A27: ='Task Tracker'!A27 -> 2 | B27: ='Task Tracker'!B27 -> Air Compressor System | C27: ='Task Tracker'!E27 -> Compressor Room Preparation | D27: ='Task Tracker'!G27 -> Not Started | E27: ='Task Tracker'!H27 -> 46191 | F27: ='Task Tracker'!I27 -> 46236
A28: ='Task Tracker'!A28 -> 2 | B28: ='Task Tracker'!B28 -> Air Compressor System | C28: ='Task Tracker'!E28 -> Equipment Installation | D28: ='Task Tracker'!G28 -> Not Started | E28: ='Task Tracker'!H28 -> 46323 | F28: ='Task Tracker'!I28 -> 46334
A29: ='Task Tracker'!A29 -> 2 | B29: ='Task Tracker'!B29 -> Air Compressor System | C29: ='Task Tracker'!E29 -> Pipe Network Connection | D29: ='Task Tracker'!G29 -> Not Started | E29: ='Task Tracker'!H29 -> 46217 | F29: ='Task Tracker'!I29 -> 46248
A30: ='Task Tracker'!A30 -> 2 | B30: ='Task Tracker'!B30 -> Air Compressor System | C30: ='Task Tracker'!E30 -> Pressure & Leak Test | D30: ='Task Tracker'!G30 -> Not Started | E30: ='Task Tracker'!H30 -> 46334 | F30: ='Task Tracker'!I30 -> 46344
A31: ='Task Tracker'!A31 -> 2 | B31: ='Task Tracker'!B31 -> Air Compressor System | C31: ='Task Tracker'!E31 -> Performance Verification | D31: ='Task Tracker'!G31 -> Not Started | E31: ='Task Tracker'!H31 -> 46344 | F31: ='Task Tracker'!I31 -> 46350
A32: ▶ SYSTEM 3 — Water System (10000 Kg/H)
A33: ='Task Tracker'!A33 -> 3 | B33: ='Task Tracker'!B33 -> Water System | C33: ='Task Tracker'!E33 -> Water Balance Study | D33: ='Task Tracker'!G33 -> Complete | E33: ='Task Tracker'!H33 -> 46140 | F33: ='Task Tracker'!I33 -> 46153
A34: ='Task Tracker'!A34 -> 3 | B34: ='Task Tracker'!B34 -> Water System | C34: ='Task Tracker'!E34 -> Plumbing Drawing Approval | D34: ='Task Tracker'!G34 -> Complete | E34: ='Task Tracker'!H34 -> 46153 | F34: ='Task Tracker'!I34 -> 46214
A35: ='Task Tracker'!A35 -> 3 | B35: ='Task Tracker'!B35 -> Water System | C35: ='Task Tracker'!E35 -> Pump & Tank Selection | D35: ='Task Tracker'!G35 -> In Progress | E35: ='Task Tracker'!H35 -> 46214 | F35: ='Task Tracker'!I35 -> 46221
A36: ='Task Tracker'!A36 -> 3 | B36: ='Task Tracker'!B36 -> Water System | C36: ='Task Tracker'!E36 -> Purchase Order Issued | D36: ='Task Tracker'!G36 -> Not Started | E36: ='Task Tracker'!H36 -> 46221 | F36: ='Task Tracker'!I36 -> 46252
A37: ='Task Tracker'!A37 -> 3 | B37: ='Task Tracker'!B37 -> Water System | C37: ='Task Tracker'!E37 -> Manufacturing / Supply | D37: ='Task Tracker'!G37 -> Not Started | E37: ='Task Tracker'!H37 -> 46252 | F37: ='Task Tracker'!I37 -> 46283
A38: ='Task Tracker'!A38 -> 3 | B38: ='Task Tracker'!B38 -> Water System | C38: ='Task Tracker'!E38 -> Shipping | D38: ='Task Tracker'!G38 -> Not Started | E38: ='Task Tracker'!H38 -> 46283 | F38: ='Task Tracker'!I38 -> 46313
A39: ='Task Tracker'!A39 -> 3 | B39: ='Task Tracker'!B39 -> Water System | C39: ='Task Tracker'!E39 -> Site Delivery | D39: ='Task Tracker'!G39 -> Not Started | E39: ='Task Tracker'!H39 -> 46313 | F39: ='Task Tracker'!I39 -> 46323
A40: ='Task Tracker'!A40 -> 3 | B40: ='Task Tracker'!B40 -> Water System | C40: ='Task Tracker'!E40 -> Trenching & Civil Works | D40: ='Task Tracker'!G40 -> Not Started | E40: ='Task Tracker'!H40 -> 46191 | F40: ='Task Tracker'!I40 -> 46236
A41: ='Task Tracker'!A41 -> 3 | B41: ='Task Tracker'!B41 -> Water System | C41: ='Task Tracker'!E41 -> Pump & Tank Installation | D41: ='Task Tracker'!G41 -> Not Started | E41: ='Task Tracker'!H41 -> 46323 | F41: ='Task Tracker'!I41 -> 46334
...
