Workbook

Sheet Lisez-moi
A1: Unité Humide – RDC Modifié (P1 RDC v8, implantation optimisée) : dimensions, panneaux sandwich et puissance frigorifique
A3: Contenu
A4: • Zones : dimensions de chaque zone (longueur, largeur, surface, périmètre, hauteur, volume), consigne, épaisseur de panneau.
A5: • Parois : chaque mur une seule fois avec ses deux côtés → métré des panneaux sans double comptage, et flux thermiques.
A6: • Portes : portes, traversées d'autoclaves et passages de convoyeurs / tunnel relevés sur le plan v8, surface déduite des murs.
A7: • Panneaux : quantités par épaisseur (murs + plafonds), chutes, prix, accessoires, portes → coût estimatif.
A8: • Bilan frigorifique : pré-dimensionnement de la puissance par zone réfrigérée.
A9: • Équipements : encombrements, poids, puissances et utilités des machines (documents fournisseurs).
A10: • Hypothèses : tous les paramètres modifiables (températures, λ, règles d'épaisseur, prix, hauteurs de portes).
A12: Légende des couleurs
A13: Texte bleu = valeur saisie (mesure sur plan ou hypothèse) · fond jaune = hypothèse à vérifier/ajuster · texte noir = formule · texte vert = lien vers une autre feuille.
A15: Points d'attention
... A21: • Les autoclaves traversants supposent la version double porte de Steriflow (à confirmer) ; sinon revenir à l'implantation v7.

Sheet Hypothèses
A1: Hypothèses et paramètres (cellules bleues sur fond jaune = à ajuster)
A3: Paramètres généraux
A4: Conductivité isolant λ (W/m.K) | B4: 0.022 | D4: Mousse PIR/PUR courante 0,022–0,025 W/m.K ; vérifier la fiche du panneau retenu.
A5: Masse volumique de l'air ρ (kg/m³) | B5: 1.2 | D5: Valeur usuelle.
A6: U sol isolé – chambres négatives (W/m².K) | B6: 0.25 | D6: Dalle isolée + hors-gel ; à confirmer par le frigoriste.
A7: U sol non isolé (W/m².K) | B7: 0.6 | D7: Dallage sur terre-plein non isolé (ordre de grandeur).
A8: Majoration (ventilateurs, dégivrage, sécurité) | B8: 0.2 | D8: Pratique courante 15–25 % en pré-dimensionnement.
A9: Chutes / pertes panneaux | B9: 0.05 | D9: Hypothèse ; dépend du calepinage.
A10: Accessoires (profils, joints, fixations) en % du coût panneaux | B10: 0.15 | D10: Hypothèse ; à remplacer par le devis.
A12: Températures des ambiances voisines (été, °C)
A13: EXT – Extérieur (façades) | B13: 40 | D13: Température de base été à Benguerir, à confirmer (données climatiques locales).
A14: TOIT – Sous toiture (au-dessus des plafonds) | B14: 40 | D14: Air sous couverture métallique en été ; hypothèse.
A15: SOL – Sol / terre-plein | B15: 20 | D15: Hypothèse.
A16: MPF – Magasin produit fini (voisin, mur ouest de l'emballage) | B16: 30 | D16: Hypothèse.
A17: ADM – Administration (mur sud des chambres) | B17: 25 | D17: Bureaux climatisés ; hypothèse.
A18: ESC – Escalier | B18: 30 | D18: Hypothèse.
A20: Épaisseur de panneau selon la température de consigne
A21: Si consigne ≤ (°C) | B21: Épaisseur (mm) | C21: Prix (MAD/m²)
A22: -15 | B22: 150 | C22: 420
A23: 5 | B23: 100 | C23: 330
A24: 15 | B24: 80 | C24: 290
A25: 99 | B25: 60 | C25: 250
A26: Règle : 1re ligne dont le seuil ≥ consigne (ordre croissant). Prix = EXEMPLES à remplacer par les devis fournisseurs.
A28: Portes (dimensions et prix unitaires)
A29: Type | B29: Hauteur (m) | C29: Prix (MAD/u)
A30: Porte double | B30: 2.1 | C30: 18000
A31: Porte simple | B31: 2.1 | C31: 9000
A32: Porte sectionnelle (quai) | B32: 3 | C32: 45000
A33: Porte rapide | B33: 3 | C33: 35000
A34: Passage tunnel | B34: 2.8 | C34: 0
A35: Traversée autoclave | B35: 2.1 | C35: 0
A36: Passage convoyeur | B36: 0.8 | C36: 0
A37: Hauteurs non cotées sur le plan : hypothèses. Prix = EXEMPLES, à remplacer.
A39: Table des ambiances (calculée – ne pas modifier)
A40: Code | B40: Température (°C) | C40: Épaisseur (mm) | D40: Panneaux ?
A41: =Zones!A5 -> Z1 | B41: =Zones!K5 -> 30 | C41: =Zones!L5 -> 60 | D41: =Zones!I5 -> Oui
A42: =Zones!A6 -> Z2 | B42: =Zones!K6 -> 30 | C42: =Zones!L6 -> 60 | D42: =Zones!I6 -> Oui
A43: =Zones!A7 -> Z3 | B43: =Zones!K7 -> 35 | C43: =Zones!L7 -> 60 | D43: =Zones!I7 -> Oui
A44: =Zones!A8 -> Z4 | B44: =Zones!K8 -> 30 | C44: =Zones!L8 -> 60 | D44: =Zones!I8 -> Oui
A45: =Zones!A9 -> Z5 | B45: =Zones!K9 -> 30 | C45: =Zones!L9 -> 60 | D45: =Zones!I9 -> Oui
...

Sheet Zones
A1: Dimensions des zones – Unité Humide (RDC Modifié)
A2: Mesuré sur P1 RDC v8.dwg (RDC Modifié – implantation optimisée), entre nus intérieurs des murs. Hauteur = hauteur des panneaux / faux-plafond isotherme : 6,00 m (HSP bâtiment 8 m).
A4: Code | B4: Zone | C4: Longueur N-S (m) | D4: Largeur E-O (m) | E4: Surface (m²) | F4: Périmètre (m) | G4: Hauteur panneaux (m) | H4: Volume (m³) | I4: Panneaux ? (Oui/Non) | J4: Réfrigérée ? (Oui/Non) | K4: Température (°C) | L4: Épaisseur panneau (mm) | M4: Surface murs nette autour de la zone (m²) | N4: Surface plafond panneaux (m²) | O4: Remarque
A5: Z1 | B5: Salle d'emballage | C5: 11.83 | D5: 24.44 | E5: =C5*D5 -> 289.1252 | F5: =2*(C5+D5) -> 72.54 | G5: 6 | H5: =E5*G5 -> 1734.7512 | I5: Oui | J5: Non | K5: 30 | L5: =IF(I5="Oui",INDEX(Hypothèses!$B$22:$B$25,MATCH(TRUE(),INDEX(Hypothèses!$A$22:$A$25>=K5,0),0)),0) -> 60 | M5: =SUMIF(Parois!$B$5:$B$53,A5,Parois!$J$5:$J$53)+SUMIF(Parois!$C$5:$C$53,A5,Parois!$J$5:$J$53)-SUMIFS(Parois!$J$5:$J$53,Parois!$B$5:$B$53,A5,Parois!$C$5:$C$53,A5) -> 428.55 | N5: =IF(I5="Oui",E5,0) -> 289.1252 | O5: Inchangée. Reçoit les boîtes du déchargeur par la porte est (convoyeur).
A6: Z2 | B6: Zone de déchargement / refroidissement | C6: 8.4 | D6: 20.34 | E6: =C6*D6 -> 170.856 | F6: =2*(C6+D6) -> 57.48 | G6: 6 | H6: =E6*G6 -> 1025.136 | I6: Oui | J6: Non | K6: 30 | L6: =IF(I6="Oui",INDEX(Hypothèses!$B$22:$B$25,MATCH(TRUE(),INDEX(Hypothèses!$A$22:$A$25>=K6,0),0)),0) -> 60 | M6: =SUMIF(Parois!$B$5:$B$53,A6,Parois!$J$5:$J$53)+SUMIF(Parois!$C$5:$C$53,A6,Parois!$J$5:$J$53)-SUMIFS(Parois!$J$5:$J$53,Parois!$B$5:$B$53,A6,Parois!$C$5:$C$53,A6) -> 317.286 | N6: =IF(I6="Oui",E6,0) -> 170.856 | O6: Côté STÉRILISÉ : portes nord des autoclaves, navette, stockage / ressuyage des paniers, déchargeur, retour paniers vides.
A7: Z3 | B7: Zone de stérilisation | C7: 7.3 | D7: 20.34 | E7: =C7*D7 -> 148.482 | F7: =2*(C7+D7) -> 55.28 | G7: 6 | H7: =E7*G7 -> 890.892 | I7: Oui | J7: Non | K7: 35 | L7: =IF(I7="Oui",INDEX(Hypothèses!$B$22:$B$25,MATCH(TRUE(),INDEX(Hypothèses!$A$22:$A$25>=K7,0),0)),0) -> 60 | M7: =SUMIF(Parois!$B$5:$B$53,A7,Parois!$J$5:$J$53)+SUMIF(Parois!$C$5:$C$53,A7,Parois!$J$5:$J$53)-SUMIFS(Parois!$J$5:$J$53,Parois!$B$5:$B$53,A7,Parois!$C$5:$C$53,A7) -> 286.152 | N7: =IF(I7="Oui",E7,0) -> 148.482 | O7: 6 autoclaves Steriflow 1300 traversants (double porte) côte à côte, portes dans les parois sud et nord ; 1,10 m côté circulation, 0,95 m entre autoclaves, 4,59 m côté façade (collecteurs + retour paniers vides).
A8: Z4 | B8: Zone de chargement paniers | C8: 5.5 | D8: 20.34 | E8: =C8*D8 -> 111.87 | F8: =2*(C8+D8) -> 51.68 | G8: 6 | H8: =E8*G8 -> 671.22 | I8: Oui | J8: Non | K8: 30 | L8: =IF(I8="Oui",INDEX(Hypothèses!$B$22:$B$25,MATCH(TRUE(),INDEX(Hypothèses!$A$22:$A$25>=K8,0),0)),0) -> 60 | M8: =SUMIF(Parois!$B$5:$B$53,A8,Parois!$J$5:$J$53)+SUMIF(Parois!$C$5:$C$53,A8,Parois!$J$5:$J$53)-SUMIFS(Parois!$J$5:$J$53,Parois!$B$5:$B$53,A8,Parois!$C$5:$C$53,A8) -> 208.566 | N8: =IF(I8="Oui",E8,0) -> 111.87 | O8: Côté NON stérilisé : 2 chargeurs de paniers + navette devant les portes sud. Ouverte sur le sertissage (13,20 m).
A9: Z5 | B9: Zone de sertissage / conditionnement | C9: L | D9: L | E9: 192.45 | F9: 66 | G9: 6 | H9: =E9*G9 -> 1154.7 | I9: Oui | J9: Non | K9: 30 | L9: =IF(I9="Oui",INDEX(Hypothèses!$B$22:$B$25,MATCH(TRUE(),INDEX(Hypothèses!$A$22:$A$25>=K9,0),0)),0) -> 60 | M9: =SUMIF(Parois!$B$5:$B$53,A9,Parois!$J$5:$J$53)+SUMIF(Parois!$C$5:$C$53,A9,Parois!$J$5:$J$53)-SUMIFS(Parois!$J$5:$J$53,Parois!$B$5:$B$53,A9,Parois!$C$5:$C$53,A9) -> 305.03 | N9: =IF(I9="Oui",E9,0) -> 192.45 | O9: 13,20 × 17,30 m moins dépalettisation et hygiène. Waldner Dosomat + ligne boîtes Zilli & Bellini → SOMME.
A10: Z6 | B10: Dépalettisation emballages vides | C10: 8.5 | D10: 3 | E10: =C10*D10 -> 25.5 | F10: =2*(C10+D10) -> 23 | G10: 6 | H10: =E10*G10 -> 153 | I10: Oui | J10: Non | K10: 30 | L10: =IF(I10="Oui",INDEX(Hypothèses!$B$22:$B$25,MATCH(TRUE(),INDEX(Hypothèses!$A$22:$A$25>=K10,0),0)),0) -> 60 | M10: =SUMIF(Parois!$B$5:$B$53,A10,Parois!$J$5:$J$53)+SUMIF(Parois!$C$5:$C$53,A10,Parois!$J$5:$J$53)-SUMIFS(Parois!$J$5:$J$53,Parois!$B$5:$B$53,A10,Parois!$C$5:$C$53,A10) -> 130.66 | N10: =IF(I10="Oui",E10,0) -> 25.5 | O10: Entrée depuis la circulation face au SAS marchandises (porte 2,00 m).
A11: Z7 | B11: Hygiène zone cuite | C11: 3.5 | D11: 2.4 | E11: =C11*D11 -> 8.4 | F11: =2*(C11+D11) -> 11.8 | G11: 6 | H11: =E11*G11 -> 50.4 | I11: Oui | J11: Non | K11: 30 | L11: =IF(I11="Oui",INDEX(Hypothèses!$B$22:$B$25,MATCH(TRUE(),INDEX(Hypothèses!$A$22:$A$25>=K11,0),0)),0) -> 60 | M11: =SUMIF(Parois!$B$5:$B$53,A11,Parois!$J$5:$J$53)+SUMIF(Parois!$C$5:$C$53,A11,Parois!$J$5:$J$53)-SUMIFS(Parois!$J$5:$J$53,Parois!$B$5:$B$53,A11,Parois!$C$5:$C$53,A11) -> 67.62 | N11: =IF(I11="Oui",E11,0) -> 8.4 | O11: Lave-mains, pédiluve, changement de tenue.
A12: Z8 | B12: Zone de cuisson / extrusion (ligne JBT) | C12: 17.3 | D12: 7.04 | E12: =C12*D12 -> 121.792 | F12: =2*(C12+D12) -> 48.68 | G12: 6 | H12: =E12*G12 -> 730.752 | I12: Oui | J12: Non | K12: 35 | L12: =IF(I12="Oui",INDEX(Hypothèses!$B$22:$B$25,MATCH(TRUE(),INDEX(Hypothèses!$A$22:$A$25>=K12,0),0)),0) -> 60 | M12: =SUMIF(Parois!$B$5:$B$53,A12,Parois!$J$5:$J$53)+SUMIF(Parois!$C$5:$C$53,A12,Parois!$J$5:$J$53)-SUMIFS(Parois!$J$5:$J$53,Parois!$B$5:$B$53,A12,Parois!$C$5:$C$53,A12) -> 283.86 | N12: =IF(I12="Oui",E12,0) -> 121.792 | O12: Tunnel vapeur JBT + refroid. + découpe ; réserve préparation sauce ; 2 extractions Ø356 en toiture (façade est).
A13: Z9 | B13: Salle de préparation viande | C13: L | D13: L | E13: 183.57 | F13: 61.88 | G13: 6 | H13: =E13*G13 -> 1101.42 | I13: Oui | J13: Oui | K13: 10 | L13: =IF(I13="Oui",INDEX(Hypothèses!$B$22:$B$25,MATCH(TRUE(),INDEX(Hypothèses!$A$22:$A$25>=K13,0),0)),0) -> 80 | M13: =SUMIF(Parois!$B$5:$B$53,A13,Parois!$J$5:$J$53)+SUMIF(Parois!$C$5:$C$53,A13,Parois!$J$5:$J$53)-SUMIFS(Parois!$J$5:$J$53,Parois!$B$5:$B$53,A13,Parois!$C$5:$C$53,A13) -> 374 | N13: =IF(I13="Oui",E13,0) -> 183.57 | O13: 20,34 × 8,40 m + 9,99 × 2,20 m (entrée viande depuis le couloir) moins hygiène. Karl Schnell + frontal JBT.
A14: Z10 | B14: Hygiène zone crue | C14: 3.6 | D14: 2.4 | E14: =C14*D14 -> 8.64 | F14: =2*(C14+D14) -> 12 | G14: 6 | H14: =E14*G14 -> 51.84 | I14: Oui | J14: Non | K14: 20 | L14: =IF(I14="Oui",INDEX(Hypothèses!$B$22:$B$25,MATCH(TRUE(),INDEX(Hypothèses!$A$22:$A$25>=K14,0),0)),0) -> 60 | M14: =SUMIF(Parois!$B$5:$B$53,A14,Parois!$J$5:$J$53)+SUMIF(Parois!$C$5:$C$53,A14,Parois!$J$5:$J$53)-SUMIFS(Parois!$J$5:$J$53,Parois!$B$5:$B$53,A14,Parois!$C$5:$C$53,A14) -> 53.82 | N14: =IF(I14="Oui",E14,0) -> 8.64 | O14: Seul accès du personnel à la zone crue.
A15: Z11 | B15: Couloir | C15: 2.8 | D15: 24.44 | E15: =C15*D15 -> 68.432 | F15: =2*(C15+D15) -> 54.48 | G15: 6 | H15: =E15*G15 -> 410.592 | I15: Oui | J15: Non | K15: 30 | L15: =IF(I15="Oui",INDEX(Hypothèses!$B$22:$B$25,MATCH(TRUE(),INDEX(Hypothèses!$A$22:$A$25>=K15,0),0)),0) -> 60 | M15: =SUMIF(Parois!$B$5:$B$53,A15,Parois!$J$5:$J$53)+SUMIF(Parois!$C$5:$C$53,A15,Parois!$J$5:$J$53)-SUMIFS(Parois!$J$5:$J$53,Parois!$B$5:$B$53,A15,Parois!$C$5:$C$53,A15) -> 327.21 | N15: =IF(I15="Oui",E15,0) -> 68.432 | O15: Recoupé en deux par une cloison avec porte.
A16: Z12 | B16: SAS quai réfrigéré | C16: 11.015 | D16: 4 | E16: =C16*D16 -> 44.06 | F16: =2*(C16+D16) -> 30.03 | G16: 6 | H16: =E16*G16 -> 264.36 | I16: Oui | J16: Oui | K16: 5 | L16: =IF(I16="Oui",INDEX(Hypothèses!$B$22:$B$25,MATCH(TRUE(),INDEX(Hypothèses!$A$22:$A$25>=K16,0),0)),0) -> 100 | M16: =SUMIF(Parois!$B$5:$B$53,A16,Parois!$J$5:$J$53)+SUMIF(Parois!$C$5:$C$53,A16,Parois!$J$5:$J$53)-SUMIFS(Parois!$J$5:$J$53,Parois!$B$5:$B$53,A16,Parois!$C$5:$C$53,A16) -> 162.87 | N16: =IF(I16="Oui",E16,0) -> 44.06 | O16: Nouveau : la porte sectionnelle du quai donne dans ce SAS (+5 °C) et non plus dans la chambre négative ; porte rapide 2,40 m vers la chambre.
A17: Z13 | B17: Chambre négative | C17: L | D17: L | E17: 244.72 | F17: 68.7 | G17: 6 | H17: =E17*G17 -> 1468.32 | I17: Oui | J17: Oui | K17: -20 | L17: =IF(I17="Oui",INDEX(Hypothèses!$B$22:$B$25,MATCH(TRUE(),INDEX(Hypothèses!$A$22:$A$25>=K17,0),0)),0) -> 150 | M17: =SUMIF(Parois!$B$5:$B$53,A17,Parois!$J$5:$J$53)+SUMIF(Parois!$C$5:$C$53,A17,Parois!$J$5:$J$53)-SUMIFS(Parois!$J$5:$J$53,Parois!$B$5:$B$53,A17,Parois!$C$5:$C$53,A17) -> 402.09 | N17: =IF(I17="Oui",E17,0) -> 244.72 | O17: Réduite par le SAS quai (4,10 × 11,12 m).
A18: Z14 | B18: Chambre positive | C18: 15.01 | D18: 5 | E18: =C18*D18 -> 75.05 | F18: =2*(C18+D18) -> 40.02 | G18: 6 | H18: =E18*G18 -> 450.3 | I18: Oui | J18: Oui | K18: 2 | L18: =IF(I18="Oui",INDEX(Hypothèses!$B$22:$B$25,MATCH(TRUE(),INDEX(Hypothèses!$A$22:$A$25>=K18,0),0)),0) -> 100 | M18: =SUMIF(Parois!$B$5:$B$53,A18,Parois!$J$5:$J$53)+SUMIF(Parois!$C$5:$C$53,A18,Parois!$J$5:$J$53)-SUMIFS(Parois!$J$5:$J$53,Parois!$B$5:$B$53,A18,Parois!$C$5:$C$53,A18) -> 237.18 | N18: =IF(I18="Oui",E18,0) -> 75.05
A19: Z15 | B19: Circulation Unité Humide (hors SAS) | C19: L | D19: L | E19: 192.8 | F19: 119.85 | G19: 6 | H19: =E19*G19 -> 1156.8 | I19: Non | J19: Non | K19: 30 | L19: =IF(I19="Oui",INDEX(Hypothèses!$B$22:$B$25,MATCH(TRUE(),INDEX(Hypothèses!$A$22:$A$25>=K19,0),0)),0) -> 0 | M19: =SUMIF(Parois!$B$5:$B$53,A19,Parois!$J$5:$J$53)+SUMIF(Parois!$C$5:$C$53,A19,Parois!$J$5:$J$53)-SUMIFS(Parois!$J$5:$J$53,Parois!$B$5:$B$53,A19,Parois!$C$5:$C$53,A19) -> 781.38 | N19: =IF(I19="Oui",E19,0) -> 0 | O19: Bande de 4,00 m le long de la façade ouest + passage vers l'escalier ; hors 2 SAS (2 × 9,35 m²).
B20: TOTAL | E20: =SUM(E5:E19) -> 1885.7472 | H20: =SUM(H5:H19) -> 11314.483 | M20: =SUM(M5:M19) -> 4366.274 | N20: =SUM(N5:N19) -> 1692.9472

Sheet Portes
A1: Portes de l'Unité Humide
A2: Mesuré sur P1 RDC v8.dwg (RDC Modifié – implantation optimisée), entre nus intérieurs des murs. Largeur = passage mesuré (blocs « Porte double 25 » = 1,40 m).
A4: N° | B4: Zone A | C4: Zone B | D4: Paroi | E4: Type | F4: Largeur (m) | G4: Hauteur (m) | H4: Surface (m²) | I4: Remarque
A5: D01 | B5: Z1 | C5: MPF | D5: P02 | E5: Porte simple | F5: 1.5 | G5: =INDEX(Hypothèses!$B$30:$B$36,MATCH(E5,Hypothèses!$A$30:$A$36,0)) -> 2.1 | H5: =F5*G5 -> 3.15 | I5: Ouverture vers le magasin produit fini.
A6: D02 | B6: Z1 | C6: Z2 | D6: P05 | E6: Porte double | F6: 1.4 | G6: =INDEX(Hypothèses!$B$30:$B$36,MATCH(E6,Hypothèses!$A$30:$A$36,0)) -> 2.1 | H6: =F6*G6 -> 2.94 | I6: Porte est existante ; passage du convoyeur déchargeur → emballage.
A7: D03 | B7: Z2 | C7: Z3 | D7: P07 | E7: Traversée autoclave | F7: 8.94 | G7: =INDEX(Hypothèses!$B$30:$B$36,MATCH(E7,Hypothèses!$A$30:$A$36,0)) -> 2.1 | H7: =F7*G7 -> 18.774 | I7: 6 × 1,49 m : portes nord des autoclaves (étanchéité inox autour des virolles).
A8: D04 | B8: Z3 | C8: Z4 | D8: P09 | E8: Traversée autoclave | F8: 8.94 | G8: =INDEX(Hypothèses!$B$30:$B$36,MATCH(E8,Hypothèses!$A$30:$A$36,0)) -> 2.1 | H8: =F8*G8 -> 18.774 | I8: 6 × 1,49 m : portes sud des autoclaves.
A9: D05 | B9: Z2 | C9: Z3 | D9: P07 | E9: Porte double | F9: 1.4 | G9: =INDEX(Hypothèses!$B$30:$B$36,MATCH(E9,Hypothèses!$A$30:$A$36,0)) -> 2.1 | H9: =F9*G9 -> 2.94 | I9: Retour paniers vides (nord).
A10: D06 | B10: Z3 | C10: Z4 | D10: P09 | E10: Porte double | F10: 1.4 | G10: =INDEX(Hypothèses!$B$30:$B$36,MATCH(E10,Hypothèses!$A$30:$A$36,0)) -> 2.1 | H10: =F10*G10 -> 2.94 | I10: Retour paniers vides (sud).
A11: D07 | B11: Z15 | C11: Z3 | D11: P11 | E11: Porte simple | F11: 1 | G11: =INDEX(Hypothèses!$B$30:$B$36,MATCH(E11,Hypothèses!$A$30:$A$36,0)) -> 2.1 | H11: =F11*G11 -> 2.1 | I11: Accès technique stérilisation.
A12: D08 | B12: Z15 | C12: Z2 | D12: P08 | E12: Porte double | F12: 1.4 | G12: =INDEX(Hypothèses!$B$30:$B$36,MATCH(E12,Hypothèses!$A$30:$A$36,0)) -> 2.1 | H12: =F12*G12 -> 2.94
A13: D09 | B13: Z15 | C13: Z6 | D13: P20 | E13: Porte double | F13: 2 | G13: =INDEX(Hypothèses!$B$30:$B$36,MATCH(E13,Hypothèses!$A$30:$A$36,0)) -> 2.1 | H13: =F13*G13 -> 4.2 | I13: Face au SAS marchandises (transpalette).
A14: D10 | B14: Z6 | C14: Z5 | D14: P19 | E14: Porte double | F14: 1.4 | G14: =INDEX(Hypothèses!$B$30:$B$36,MATCH(E14,Hypothèses!$A$30:$A$36,0)) -> 2.1 | H14: =F14*G14 -> 2.94
A15: D11 | B15: Z6 | C15: Z5 | D15: P19 | E15: Passage convoyeur | F15: 1 | G15: =INDEX(Hypothèses!$B$30:$B$36,MATCH(E15,Hypothèses!$A$30:$A$36,0)) -> 0.8 | H15: =F15*G15 -> 0.8 | I15: Convoyeur emballages vides.
A16: D12 | B16: Z15 | C16: Z7 | D16: P22 | E16: Porte simple | F16: 0.9 | G16: =INDEX(Hypothèses!$B$30:$B$36,MATCH(E16,Hypothèses!$A$30:$A$36,0)) -> 2.1 | H16: =F16*G16 -> 1.89
A17: D13 | B17: Z7 | C17: Z5 | D17: P21 | E17: Porte simple | F17: 0.9 | G17: =INDEX(Hypothèses!$B$30:$B$36,MATCH(E17,Hypothèses!$A$30:$A$36,0)) -> 2.1 | H17: =F17*G17 -> 1.89
A18: D14 | B18: Z5 | C18: Z8 | D18: P15 | E18: Porte double | F18: 1.4 | G18: =INDEX(Hypothèses!$B$30:$B$36,MATCH(E18,Hypothèses!$A$30:$A$36,0)) -> 2.1 | H18: =F18*G18 -> 2.94
A19: D15 | B19: Z5 | C19: Z8 | D19: P15 | E19: Passage convoyeur | F19: 1 | G19: =INDEX(Hypothèses!$B$30:$B$36,MATCH(E19,Hypothèses!$A$30:$A$36,0)) -> 0.8 | H19: =F19*G19 -> 0.8 | I19: Convoyeur morceaux découpe → remplisseuse.
A20: D16 | B20: Z8 | C20: Z9 | D20: P18 | E20: Passage tunnel | F20: 1.6 | G20: =INDEX(Hypothèses!$B$30:$B$36,MATCH(E20,Hypothèses!$A$30:$A$36,0)) -> 2.8 | H20: =F20*G20 -> 4.48 | I20: Traversée JBT extrudeuse → tunnel (calfeutrement étanche) ; aucune porte crue → cuite.
A21: D17 | B21: Z15 | C21: Z10 | D21: P32 | E21: Porte simple | F21: 0.9 | G21: =INDEX(Hypothèses!$B$30:$B$36,MATCH(E21,Hypothèses!$A$30:$A$36,0)) -> 2.1 | H21: =F21*G21 -> 1.89
A22: D18 | B22: Z10 | C22: Z9 | D22: P31 | E22: Porte simple | F22: 0.9 | G22: =INDEX(Hypothèses!$B$30:$B$36,MATCH(E22,Hypothèses!$A$30:$A$36,0)) -> 2.1 | H22: =F22*G22 -> 1.89
A23: D19 | B23: Z9 | C23: Z11 | D23: P30 | E23: Porte double | F23: 1.4 | G23: =INDEX(Hypothèses!$B$30:$B$36,MATCH(E23,Hypothèses!$A$30:$A$36,0)) -> 2.1 | H23: =F23*G23 -> 2.94 | I23: Entrée viande depuis les chambres.
A24: D20 | B24: Z11 | C24: Z11 | D24: P37 | E24: Porte double | F24: 1.4 | G24: =INDEX(Hypothèses!$B$30:$B$36,MATCH(E24,Hypothèses!$A$30:$A$36,0)) -> 2.1 | H24: =F24*G24 -> 2.94 | I24: Cloison intérieure du couloir.
A25: D21 | B25: Z11 | C25: Z13 | D25: P38 | E25: Porte double | F25: 1.4 | G25: =INDEX(Hypothèses!$B$30:$B$36,MATCH(E25,Hypothèses!$A$30:$A$36,0)) -> 2.1 | H25: =F25*G25 -> 2.94 | I25: Porte est de la chambre négative.
A26: D22 | B26: Z11 | C26: Z12 | D26: P39 | E26: Porte double | F26: 1.4 | G26: =INDEX(Hypothèses!$B$30:$B$36,MATCH(E26,Hypothèses!$A$30:$A$36,0)) -> 2.1 | H26: =F26*G26 -> 2.94 | I26: Ancienne porte ouest de la chambre négative → SAS quai.
A27: D23 | B27: Z11 | C27: Z14 | D27: P40 | E27: Porte double | F27: 1.4 | G27: =INDEX(Hypothèses!$B$30:$B$36,MATCH(E27,Hypothèses!$A$30:$A$36,0)) -> 2.1 | H27: =F27*G27 -> 2.94
A28: D24 | B28: Z12 | C28: EXT | D28: P42 | E28: Porte sectionnelle (quai) | F28: 2.8 | G28: =INDEX(Hypothèses!$B$30:$B$36,MATCH(E28,Hypothèses!$A$30:$A$36,0)) -> 3 | H28: =F28*G28 -> 8.4 | I28: Quai de déchargement (inchangé) → SAS quai réfrigéré.
A29: D25 | B29: Z12 | C29: Z13 | D29: P44 | E29: Porte rapide | F29: 2.4 | G29: =INDEX(Hypothèses!$B$30:$B$36,MATCH(E29,Hypothèses!$A$30:$A$36,0)) -> 3 | H29: =F29*G29 -> 7.2 | I29: Porte rapide isotherme SAS quai → chambre négative.
A30: D26 | B30: Z15 | C30: EXT | D30: P48 | E30: Porte double | F30: 1.4 | G30: =INDEX(Hypothèses!$B$30:$B$36,MATCH(E30,Hypothèses!$A$30:$A$36,0)) -> 2.1 | H30: =F30*G30 -> 2.94 | I30: SAS nord – porte de façade.
A31: D27 | B31: Z15 | C31: EXT | D31: P48 | E31: Porte double | F31: 1.4 | G31: =INDEX(Hypothèses!$B$30:$B$36,MATCH(E31,Hypothèses!$A$30:$A$36,0)) -> 2.1 | H31: =F31*G31 -> 2.94 | I31: SAS sud – porte de façade.
A32: D28 | B32: Z15 | C32: Z15 | D32: P49 | E32: Porte double | F32: 1.4 | G32: =INDEX(Hypothèses!$B$30:$B$36,MATCH(E32,Hypothèses!$A$30:$A$36,0)) -> 2.1 | H32: =F32*G32 -> 2.94 | I32: SAS nord – porte intérieure.
A33: D29 | B33: Z15 | C33: Z15 | D33: P49 | E33: Porte double | F33: 1.4 | G33: =INDEX(Hypothèses!$B$30:$B$36,MATCH(E33,Hypothèses!$A$30:$A$36,0)) -> 2.1 | H33: =F33*G33 -> 2.94 | I33: SAS sud – porte intérieure.

Sheet Parois
A1: Parois (chaque mur compté une seule fois) – longueurs mesurées sur le plan
A2: Mesuré sur P1 RDC v8.dwg (RDC Modifié – implantation optimisée), entre nus intérieurs des murs. Hauteur = max des hauteurs des zones de part et d'autre ; épaisseur = max des épaisseurs requises ; Q = flux entrant par la paroi (W) vers la zone la plus froide.
A4: Paroi | B4: Zone A | C4: Zone B | D4: Description | E4: Longueur (m) | F4: Hauteur (m) | G4: Surface brute (m²) | H4: Surface portes (m²) | I4: Panneaux ? | J4: Surface nette (m²) | K4: Épaisseur (mm) | L4: U (W/m².K) | M4: T zone A (°C) | N4: T zone B (°C) | O4: Flux vers A (W) | P4: Flux vers B (W)
A5: P01 | B5: Z1 | C5: EXT | D5: Emballage – façade nord | E5: 24.44 | F5: =MAX(IFERROR(INDEX(Zones!$G$5:$G$19,MATCH(B5,Zones!$A$5:$A$19,0)),0),IFERROR(INDEX(Zones!$G$5:$G$19,MATCH(C5,Zones!$A$5:$A$19,0)),0)) -> 6 | G5: =E5*F5 -> 146.64 | H5: =SUMIF(Portes!$D$5:$D$33,A5,Portes!$H$5:$H$33) -> 0 | I5: =IF(OR(INDEX(Hypothèses!$D$41:$D$61,MATCH(B5,Hypothèses!$A$41:$A$61,0))="Oui",INDEX(Hypothèses!$D$41:$D$61,MATCH(C5,Hypothèses!$A$41:$A$61,0))="Oui"),"Oui","Non") -> Oui | J5: =MAX(0,G5-H5) -> 146.64 | K5: =IF(I5="Oui",MAX(INDEX(Hypothèses!$C$41:$C$61,MATCH(B5,Hypothèses!$A$41:$A$61,0)),INDEX(Hypothèses!$C$41:$C$61,MATCH(C5,Hypothèses!$A$41:$A$61,0))),0) -> 60 | L5: =IF(K5>0,Hypothèses!$B$4/(K5/1000),0) -> 0.36666667 | M5: =INDEX(Hypothèses!$B$41:$B$61,MATCH(B5,Hypothèses!$A$41:$A$61,0)) -> 30 | N5: =INDEX(Hypothèses!$B$41:$B$61,MATCH(C5,Hypothèses!$A$41:$A$61,0)) -> 40 | O5: =L5*J5*MAX(0,N5-M5) -> 537.68 | P5: =L5*J5*MAX(0,M5-N5) -> 0
A6: P02 | B6: Z1 | C6: MPF | D6: Emballage – mur ouest (magasin produit fini) | E6: 11.83 | F6: =MAX(IFERROR(INDEX(Zones!$G$5:$G$19,MATCH(B6,Zones!$A$5:$A$19,0)),0),IFERROR(INDEX(Zones!$G$5:$G$19,MATCH(C6,Zones!$A$5:$A$19,0)),0)) -> 6 | G6: =E6*F6 -> 70.98 | H6: =SUMIF(Portes!$D$5:$D$33,A6,Portes!$H$5:$H$33) -> 3.15 | I6: =IF(OR(INDEX(Hypothèses!$D$41:$D$61,MATCH(B6,Hypothèses!$A$41:$A$61,0))="Oui",INDEX(Hypothèses!$D$41:$D$61,MATCH(C6,Hypothèses!$A$41:$A$61,0))="Oui"),"Oui","Non") -> Oui | J6: =MAX(0,G6-H6) -> 67.83 | K6: =IF(I6="Oui",MAX(INDEX(Hypothèses!$C$41:$C$61,MATCH(B6,Hypothèses!$A$41:$A$61,0)),INDEX(Hypothèses!$C$41:$C$61,MATCH(C6,Hypothèses!$A$41:$A$61,0))),0) -> 60 | L6: =IF(K6>0,Hypothèses!$B$4/(K6/1000),0) -> 0.36666667 | M6: =INDEX(Hypothèses!$B$41:$B$61,MATCH(B6,Hypothèses!$A$41:$A$61,0)) -> 30 | N6: =INDEX(Hypothèses!$B$41:$B$61,MATCH(C6,Hypothèses!$A$41:$A$61,0)) -> 30 | O6: =L6*J6*MAX(0,N6-M6) -> 0 | P6: =L6*J6*MAX(0,M6-N6) -> 0
A7: P03 | B7: Z1 | C7: EXT | D7: Emballage – façade est | E7: 11.83 | F7: =MAX(IFERROR(INDEX(Zones!$G$5:$G$19,MATCH(B7,Zones!$A$5:$A$19,0)),0),IFERROR(INDEX(Zones!$G$5:$G$19,MATCH(C7,Zones!$A$5:$A$19,0)),0)) -> 6 | G7: =E7*F7 -> 70.98 | H7: =SUMIF(Portes!$D$5:$D$33,A7,Portes!$H$5:$H$33) -> 0 | I7: =IF(OR(INDEX(Hypothèses!$D$41:$D$61,MATCH(B7,Hypothèses!$A$41:$A$61,0))="Oui",INDEX(Hypothèses!$D$41:$D$61,MATCH(C7,Hypothèses!$A$41:$A$61,0))="Oui"),"Oui","Non") -> Oui | J7: =MAX(0,G7-H7) -> 70.98 | K7: =IF(I7="Oui",MAX(INDEX(Hypothèses!$C$41:$C$61,MATCH(B7,Hypothèses!$A$41:$A$61,0)),INDEX(Hypothèses!$C$41:$C$61,MATCH(C7,Hypothèses!$A$41:$A$61,0))),0) -> 60 | L7: =IF(K7>0,Hypothèses!$B$4/(K7/1000),0) -> 0.36666667 | M7: =INDEX(Hypothèses!$B$41:$B$61,MATCH(B7,Hypothèses!$A$41:$A$61,0)) -> 30 | N7: =INDEX(Hypothèses!$B$41:$B$61,MATCH(C7,Hypothèses!$A$41:$A$61,0)) -> 40 | O7: =L7*J7*MAX(0,N7-M7) -> 260.26 | P7: =L7*J7*MAX(0,M7-N7) -> 0
A8: P04 | B8: Z1 | C8: Z15 | D8: Emballage / circulation | E8: 4 | F8: =MAX(IFERROR(INDEX(Zones!$G$5:$G$19,MATCH(B8,Zones!$A$5:$A$19,0)),0),IFERROR(INDEX(Zones!$G$5:$G$19,MATCH(C8,Zones!$A$5:$A$19,0)),0)) -> 6 | G8: =E8*F8 -> 24 | H8: =SUMIF(Portes!$D$5:$D$33,A8,Portes!$H$5:$H$33) -> 0 | I8: =IF(OR(INDEX(Hypothèses!$D$41:$D$61,MATCH(B8,Hypothèses!$A$41:$A$61,0))="Oui",INDEX(Hypothèses!$D$41:$D$61,MATCH(C8,Hypothèses!$A$41:$A$61,0))="Oui"),"Oui","Non") -> Oui | J8: =MAX(0,G8-H8) -> 24 | K8: =IF(I8="Oui",MAX(INDEX(Hypothèses!$C$41:$C$61,MATCH(B8,Hypothèses!$A$41:$A$61,0)),INDEX(Hypothèses!$C$41:$C$61,MATCH(C8,Hypothèses!$A$41:$A$61,0))),0) -> 60 | L8: =IF(K8>0,Hypothèses!$B$4/(K8/1000),0) -> 0.36666667 | M8: =INDEX(Hypothèses!$B$41:$B$61,MATCH(B8,Hypothèses!$A$41:$A$61,0)) -> 30 | N8: =INDEX(Hypothèses!$B$41:$B$61,MATCH(C8,Hypothèses!$A$41:$A$61,0)) -> 30 | O8: =L8*J8*MAX(0,N8-M8) -> 0 | P8: =L8*J8*MAX(0,M8-N8) -> 0
A9: P05 | B9: Z1 | C9: Z2 | D9: Emballage / déchargement | E9: 20.34 | F9: =MAX(IFERROR(INDEX(Zones!$G$5:$G$19,MATCH(B9,Zones!$A$5:$A$19,0)),0),IFERROR(INDEX(Zones!$G$5:$G$19,MATCH(C9,Zones!$A$5:$A$19,0)),0)) -> 6 | G9: =E9*F9 -> 122.04 | H9: =SUMIF(Portes!$D$5:$D$33,A9,Portes!$H$5:$H$33) -> 2.94 | I9: =IF(OR(INDEX(Hypothèses!$D$41:$D$61,MATCH(B9,Hypothèses!$A$41:$A$61,0))="Oui",INDEX(Hypothèses!$D$41:$D$61,MATCH(C9,Hypothèses!$A$41:$A$61,0))="Oui"),"Oui","Non") -> Oui | J9: =MAX(0,G9-H9) -> 119.1 | K9: =IF(I9="Oui",MAX(INDEX(Hypothèses!$C$41:$C$61,MATCH(B9,Hypothèses!$A$41:$A$61,0)),INDEX(Hypothèses!$C$41:$C$61,MATCH(C9,Hypothèses!$A$41:$A$61,0))),0) -> 60 | L9: =IF(K9>0,Hypothèses!$B$4/(K9/1000),0) -> 0.36666667 | M9: =INDEX(Hypothèses!$B$41:$B$61,MATCH(B9,Hypothèses!$A$41:$A$61,0)) -> 30 | N9: =INDEX(Hypothèses!$B$41:$B$61,MATCH(C9,Hypothèses!$A$41:$A$61,0)) -> 30 | O9: =L9*J9*MAX(0,N9-M9) -> 0 | P9: =L9*J9*MAX(0,M9-N9) -> 0
A10: P06 | B10: Z2 | C10: EXT | D10: Déchargement – façade est | E10: 8.4 | F10: =MAX(IFERROR(INDEX(Zones!$G$5:$G$19,MATCH(B10,Zones!$A$5:$A$19,0)),0),IFERROR(INDEX(Zones!$G$5:$G$19,MATCH(C10,Zones!$A$5:$A$19,0)),0)) -> 6 | G10: =E10*F10 -> 50.4 | H10: =SUMIF(Portes!$D$5:$D$33,A10,Portes!$H$5:$H$33) -> 0 | I10: =IF(OR(INDEX(Hypothèses!$D$41:$D$61,MATCH(B10,Hypothèses!$A$41:$A$61,0))="Oui",INDEX(Hypothèses!$D$41:$D$61,MATCH(C10,Hypothèses!$A$41:$A$61,0))="Oui"),"Oui","Non") -> Oui | J10: =MAX(0,G10-H10) -> 50.4 | K10: =IF(I10="Oui",MAX(INDEX(Hypothèses!$C$41:$C$61,MATCH(B10,Hypothèses!$A$41:$A$61,0)),INDEX(Hypothèses!$C$41:$C$61,MATCH(C10,Hypothèses!$A$41:$A$61,0))),0) -> 60 | L10: =IF(K10>0,Hypothèses!$B$4/(K10/1000),0) -> 0.36666667 | M10: =INDEX(Hypothèses!$B$41:$B$61,MATCH(B10,Hypothèses!$A$41:$A$61,0)) -> 30 | N10: =INDEX(Hypothèses!$B$41:$B$61,MATCH(C10,Hypothèses!$A$41:$A$61,0)) -> 40 | O10: =L10*J10*MAX(0,N10-M10) -> 184.8 | P10: =L10*J10*MAX(0,M10-N10) -> 0
A11: P07 | B11: Z2 | C11: Z3 | D11: Déchargement / stérilisation (portes nord autoclaves) | E11: 20.34 | F11: =MAX(IFERROR(INDEX(Zones!$G$5:$G$19,MATCH(B11,Zones!$A$5:$A$19,0)),0),IFERROR(INDEX(Zones!$G$5:$G$19,MATCH(C11,Zones!$A$5:$A$19,0)),0)) -> 6 | G11: =E11*F11 -> 122.04 | H11: =SUMIF(Portes!$D$5:$D$33,A11,Portes!$H$5:$H$33) -> 21.714 | I11: =IF(OR(INDEX(Hypothèses!$D$41:$D$61,MATCH(B11,Hypothèses!$A$41:$A$61,0))="Oui",INDEX(Hypothèses!$D$41:$D$61,MATCH(C11,Hypothèses!$A$41:$A$61,0))="Oui"),"Oui","Non") -> Oui | J11: =MAX(0,G11-H11) -> 100.326 | K11: =IF(I11="Oui",MAX(INDEX(Hypothèses!$C$41:$C$61,MATCH(B11,Hypothèses!$A$41:$A$61,0)),INDEX(Hypothèses!$C$41:$C$61,MATCH(C11,Hypothèses!$A$41:$A$61,0))),0) -> 60 | L11: =IF(K11>0,Hypothèses!$B$4/(K11/1000),0) -> 0.36666667 | M11: =INDEX(Hypothèses!$B$41:$B$61,MATCH(B11,Hypothèses!$A$41:$A$61,0)) -> 30 | N11: =INDEX(Hypothèses!$B$41:$B$61,MATCH(C11,Hypothèses!$A$41:$A$61,0)) -> 35 | O11: =L11*J11*MAX(0,N11-M11) -> 183.931 | P11: =L11*J11*MAX(0,M11-N11) -> 0
A12: P08 | B12: Z2 | C12: Z15 | D12: Déchargement / circulation | E12: 8.4 | F12: =MAX(IFERROR(INDEX(Zones!$G$5:$G$19,MATCH(B12,Zones!$A$5:$A$19,0)),0),IFERROR(INDEX(Zones!$G$5:$G$19,MATCH(C12,Zones!$A$5:$A$19,0)),0)) -> 6 | G12: =E12*F12 -> 50.4 | H12: =SUMIF(Portes!$D$5:$D$33,A12,Portes!$H$5:$H$33) -> 2.94 | I12: =IF(OR(INDEX(Hypothèses!$D$41:$D$61,MATCH(B12,Hypothèses!$A$41:$A$61,0))="Oui",INDEX(Hypothèses!$D$41:$D$61,MATCH(C12,Hypothèses!$A$41:$A$61,0))="Oui"),"Oui","Non") -> Oui | J12: =MAX(0,G12-H12) -> 47.46 | K12: =IF(I12="Oui",MAX(INDEX(Hypothèses!$C$41:$C$61,MATCH(B12,Hypothèses!$A$41:$A$61,0)),INDEX(Hypothèses!$C$41:$C$61,MATCH(C12,Hypothèses!$A$41:$A$61,0))),0) -> 60 | L12: =IF(K12>0,Hypothèses!$B$4/(K12/1000),0) -> 0.36666667 | M12: =INDEX(Hypothèses!$B$41:$B$61,MATCH(B12,Hypothèses!$A$41:$A$61,0)) -> 30 | N12: =INDEX(Hypothèses!$B$41:$B$61,MATCH(C12,Hypothèses!$A$41:$A$61,0)) -> 30 | O12: =L12*J12*MAX(0,N12-M12) -> 0 | P12: =L12*J12*MAX(0,M12-N12) -> 0
A13: P09 | B13: Z3 | C13: Z4 | D13: Stérilisation / chargement (portes sud autoclaves) | E13: 20.34 | F13: =MAX(IFERROR(INDEX(Zones!$G$5:$G$19,MATCH(B13,Zones!$A$5:$A$19,0)),0),IFERROR(INDEX(Zones!$G$5:$G$19,MATCH(C13,Zones!$A$5:$A$19,0)),0)) -> 6 | G13: =E13*F13 -> 122.04 | H13: =SUMIF(Portes!$D$5:$D$33,A13,Portes!$H$5:$H$33) -> 21.714 | I13: =IF(OR(INDEX(Hypothèses!$D$41:$D$61,MATCH(B13,Hypothèses!$A$41:$A$61,0))="Oui",INDEX(Hypothèses!$D$41:$D$61,MATCH(C13,Hypothèses!$A$41:$A$61,0))="Oui"),"Oui","Non") -> Oui | J13: =MAX(0,G13-H13) -> 100.326 | K13: =IF(I13="Oui",MAX(INDEX(Hypothèses!$C$41:$C$61,MATCH(B13,Hypothèses!$A$41:$A$61,0)),INDEX(Hypothèses!$C$41:$C$61,MATCH(C13,Hypothèses!$A$41:$A$61,0))),0) -> 60 | L13: =IF(K13>0,Hypothèses!$B$4/(K13/1000),0) -> 0.36666667 | M13: =INDEX(Hypothèses!$B$41:$B$61,MATCH(B13,Hypothèses!$A$41:$A$61,0)) -> 35 | N13: =INDEX(Hypothèses!$B$41:$B$61,MATCH(C13,Hypothèses!$A$41:$A$61,0)) -> 30 | O13: =L13*J13*MAX(0,N13-M13) -> 0 | P13: =L13*J13*MAX(0,M13-N13) -> 183.931
A14: P10 | B14: Z3 | C14: EXT | D14: Stérilisation – façade est | E14: 7.3 | F14: =MAX(IFERROR(INDEX(Zones!$G$5:$G$19,MATCH(B14,Zones!$A$5:$A$19,0)),0),IFERROR(INDEX(Zones!$G$5:$G$19,MATCH(C14,Zones!$A$5:$A$19,0)),0)) -> 6 | G14: =E14*F14 -> 43.8 | H14: =SUMIF(Portes!$D$5:$D$33,A14,Portes!$H$5:$H$33) -> 0 | I14: =IF(OR(INDEX(Hypothèses!$D$41:$D$61,MATCH(B14,Hypothèses!$A$41:$A$61,0))="Oui",INDEX(Hypothèses!$D$41:$D$61,MATCH(C14,Hypothèses!$A$41:$A$61,0))="Oui"),"Oui","Non") -> Oui | J14: =MAX(0,G14-H14) -> 43.8 | K14: =IF(I14="Oui",MAX(INDEX(Hypothèses!$C$41:$C$61,MATCH(B14,Hypothèses!$A$41:$A$61,0)),INDEX(Hypothèses!$C$41:$C$61,MATCH(C14,Hypothèses!$A$41:$A$61,0))),0) -> 60 | L14: =IF(K14>0,Hypothèses!$B$4/(K14/1000),0) -> 0.36666667 | M14: =INDEX(Hypothèses!$B$41:$B$61,MATCH(B14,Hypothèses!$A$41:$A$61,0)) -> 35 | N14: =INDEX(Hypothèses!$B$41:$B$61,MATCH(C14,Hypothèses!$A$41:$A$61,0)) -> 40 | O14: =L14*J14*MAX(0,N14-M14) -> 80.3 | P14: =L14*J14*MAX(0,M14-N14) -> 0
A15: P11 | B15: Z3 | C15: Z15 | D15: Stérilisation / circulation | E15: 7.3 | F15: =MAX(IFERROR(INDEX(Zones!$G$5:$G$19,MATCH(B15,Zones!$A$5:$A$19,0)),0),IFERROR(INDEX(Zones!$G$5:$G$19,MATCH(C15,Zones!$A$5:$A$19,0)),0)) -> 6 | G15: =E15*F15 -> 43.8 | H15: =SUMIF(Portes!$D$5:$D$33,A15,Portes!$H$5:$H$33) -> 2.1 | I15: =IF(OR(INDEX(Hypothèses!$D$41:$D$61,MATCH(B15,Hypothèses!$A$41:$A$61,0))="Oui",INDEX(Hypothèses!$D$41:$D$61,MATCH(C15,Hypothèses!$A$41:$A$61,0))="Oui"),"Oui","Non") -> Oui | J15: =MAX(0,G15-H15) -> 41.7 | K15: =IF(I15="Oui",MAX(INDEX(Hypothèses!$C$41:$C$61,MATCH(B15,Hypothèses!$A$41:$A$61,0)),INDEX(Hypothèses!$C$41:$C$61,MATCH(C15,Hypothèses!$A$41:$A$61,0))),0) -> 60 | L15: =IF(K15>0,Hypothèses!$B$4/(K15/1000),0) -> 0.36666667 | M15: =INDEX(Hypothèses!$B$41:$B$61,MATCH(B15,Hypothèses!$A$41:$A$61,0)) -> 35 | N15: =INDEX(Hypothèses!$B$41:$B$61,MATCH(C15,Hypothèses!$A$41:$A$61,0)) -> 30 | O15: =L15*J15*MAX(0,N15-M15) -> 0 | P15: =L15*J15*MAX(0,M15-N15) -> 76.45
A16: P12 | B16: Z4 | C16: EXT | D16: Chargement – façade est | E16: 5.5 | F16: =MAX(IFERROR(INDEX(Zones!$G$5:$G$19,MATCH(B16,Zones!$A$5:$A$19,0)),0),IFERROR(INDEX(Zones!$G$5:$G$19,MATCH(C16,Zones!$A$5:$A$19,0)),0)) -> 6 | G16: =E16*F16 -> 33 | H16: =SUMIF(Portes!$D$5:$D$33,A16,Portes!$H$5:$H$33) -> 0 | I16: =IF(OR(INDEX(Hypothèses!$D$41:$D$61,MATCH(B16,Hypothèses!$A$41:$A$61,0))="Oui",INDEX(Hypothèses!$D$41:$D$61,MATCH(C16,Hypothèses!$A$41:$A$61,0))="Oui"),"Oui","Non") -> Oui | J16: =MAX(0,G16-H16) -> 33 | K16: =IF(I16="Oui",MAX(INDEX(Hypothèses!$C$41:$C$61,MATCH(B16,Hypothèses!$A$41:$A$61,0)),INDEX(Hypothèses!$C$41:$C$61,MATCH(C16,Hypothèses!$A$41:$A$61,0))),0) -> 60 | L16: =IF(K16>0,Hypothèses!$B$4/(K16/1000),0) -> 0.36666667 | M16: =INDEX(Hypothèses!$B$41:$B$61,MATCH(B16,Hypothèses!$A$41:$A$61,0)) -> 30 | N16: =INDEX(Hypothèses!$B$41:$B$61,MATCH(C16,Hypothèses!$A$41:$A$61,0)) -> 40 | O16: =L16*J16*MAX(0,N16-M16) -> 121 | P16: =L16*J16*MAX(0,M16-N16) -> 0
... A53: P49 | B53: Z15 | C53: Z15 | D53: Parois des 2 SAS (2 × (2 × 2,60 + 3,60)) | E53: 17.6 | F53: =MAX(IFERROR(INDEX(Zones!$G$5:$G$19,MATCH(B53,Zones!$A$5:$A$19,0)),0),IFERROR(INDEX(Zones!$G$5:$G$19,MATCH(C53,Zones!$A$5:$A$19,0)),0)) -> 6 | G53: =E53*F53 -> 105.6 | H53: =SUMIF(Portes!$D$5:$D$33,A53,Portes!$H$5:$H$33) -> 5.88 | I53: =IF(OR(INDEX(Hypothèses!$D$41:$D$61,MATCH(B53,Hypothèses!$A$41:$A$61,0))="Oui",INDEX(Hypothèses!$D$41:$D$61,MATCH(C53,Hypothèses!$A$41:$A$61,0))="Oui"),"Oui","Non") -> Non | J53: =MAX(0,G53-H53) -> 99.72 | K53: =IF(I53="Oui",MAX(INDEX(Hypothèses!$C$41:$C$61,MATCH(B53,Hypothèses!$A$41:$A$61,0)),INDEX(Hypothèses!$C$41:$C$61,MATCH(C53,Hypothèses!$A$41:$A$61,0))),0) -> 0 | L53: =IF(K53>0,Hypothèses!$B$4/(K53/1000),0) -> 0 | M53: =INDEX(Hypothèses!$B$41:$B$61,MATCH(B53,Hypothèses!$A$41:$A$61,0)) -> 30 | N53: =INDEX(Hypothèses!$B$41:$B$61,MATCH(C53,Hypothèses!$A$41:$A$61,0)) -> 30 | O53: =L53*J53*MAX(0,N53-M53) -> 0 | P53: =L53*J53*MAX(0,M53-N53) -> 0
D54: TOTAL | E54: =SUM(E5:E53) -> 500.235 | G54: =SUM(G5:G53) -> 3001.41 | H54: =SUM(H5:H53) -> 120.338 | J54: =SUM(J5:J53) -> 2881.072
D56: Pas de paroi entre Z4 (chargement paniers) et Z5 (sertissage) : zone ouverte sur 13,20 m.

Sheet Panneaux
A1: Métré et estimation des panneaux sandwich
A2: Murs : feuille Parois (chaque mur une fois) ; plafonds : feuille Zones. Prix : feuille Hypothèses (EXEMPLES à remplacer).
A4: Épaisseur (mm) | B4: Murs (m²) | C4: Plafonds (m²) | D4: Total net (m²) | E4: Avec chutes (m²) | F4: Prix (MAD/m²) | G4: Coût panneaux (MAD)
A5: =Hypothèses!B22 -> 150 | B5: =SUMIFS(Parois!$J$5:$J$53,Parois!$K$5:$K$53,A5,Parois!$I$5:$I$53,"Oui") -> 402.09 | C5: =SUMIF(Zones!$L$5:$L$19,A5,Zones!$N$5:$N$19) -> 244.72 | D5: =B5+C5 -> 646.81 | E5: =D5*(1+Hypothèses!$B$9) -> 679.1505 | F5: =Hypothèses!C22 -> 420 | G5: =E5*F5 -> 285243.21
A6: =Hypothèses!B23 -> 100 | B6: =SUMIFS(Parois!$J$5:$J$53,Parois!$K$5:$K$53,A6,Parois!$I$5:$I$53,"Oui") -> 225.87 | C6: =SUMIF(Zones!$L$5:$L$19,A6,Zones!$N$5:$N$19) -> 119.11 | D6: =B6+C6 -> 344.98 | E6: =D6*(1+Hypothèses!$B$9) -> 362.229 | F6: =Hypothèses!C23 -> 330 | G6: =E6*F6 -> 119535.57
A7: =Hypothèses!B24 -> 80 | B7: =SUMIFS(Parois!$J$5:$J$53,Parois!$K$5:$K$53,A7,Parois!$I$5:$I$53,"Oui") -> 374 | C7: =SUMIF(Zones!$L$5:$L$19,A7,Zones!$N$5:$N$19) -> 183.57 | D7: =B7+C7 -> 557.57 | E7: =D7*(1+Hypothèses!$B$9) -> 585.4485 | F7: =Hypothèses!C24 -> 290 | G7: =E7*F7 -> 169780.07
A8: =Hypothèses!B25 -> 60 | B8: =SUMIFS(Parois!$J$5:$J$53,Parois!$K$5:$K$53,A8,Parois!$I$5:$I$53,"Oui") -> 1488.272 | C8: =SUMIF(Zones!$L$5:$L$19,A8,Zones!$N$5:$N$19) -> 1145.5472 | D8: =B8+C8 -> 2633.8192 | E8: =D8*(1+Hypothèses!$B$9) -> 2765.5102 | F8: =Hypothèses!C25 -> 250 | G8: =E8*F8 -> 691377.54
A9: TOTAL | B9: =SUM(B5:B8) -> 2490.232 | C9: =SUM(C5:C8) -> 1692.9472 | D9: =SUM(D5:D8) -> 4183.1792 | E9: =SUM(E5:E8) -> 4392.3382 | G9: =SUM(G5:G8) -> 1265936.4
A10: Accessoires | G10: =G9*Hypothèses!$B$10 -> 189890.46
A12: Portes – type | B12: Nombre | C12: Prix (MAD/u) | D12: Coût (MAD)
A13: =Hypothèses!A30 -> Porte double | B13: =COUNTIF(Portes!$E$5:$E$33,A13) -> 16 | C13: =Hypothèses!C30 -> 18000 | D13: =B13*C13 -> 288000
A14: =Hypothèses!A31 -> Porte simple | B14: =COUNTIF(Portes!$E$5:$E$33,A14) -> 6 | C14: =Hypothèses!C31 -> 9000 | D14: =B14*C14 -> 54000
A15: =Hypothèses!A32 -> Porte sectionnelle (quai) | B15: =COUNTIF(Portes!$E$5:$E$33,A15) -> 1 | C15: =Hypothèses!C32 -> 45000 | D15: =B15*C15 -> 45000
A16: =Hypothèses!A33 -> Porte rapide | B16: =COUNTIF(Portes!$E$5:$E$33,A16) -> 1 | C16: =Hypothèses!C33 -> 35000 | D16: =B16*C16 -> 35000
A17: =Hypothèses!A34 -> Passage tunnel | B17: =COUNTIF(Portes!$E$5:$E$33,A17) -> 1 | C17: =Hypothèses!C34 -> 0 | D17: =B17*C17 -> 0
A18: =Hypothèses!A35 -> Traversée autoclave | B18: =COUNTIF(Portes!$E$5:$E$33,A18) -> 2 | C18: =Hypothèses!C35 -> 0 | D18: =B18*C18 -> 0
A19: =Hypothèses!A36 -> Passage convoyeur | B19: =COUNTIF(Portes!$E$5:$E$33,A19) -> 2 | C19: =Hypothèses!C36 -> 0 | D19: =B19*C19 -> 0
A20: TOTAL portes | D20: =SUM(D13:D19) -> 422000
A22: TOTAL panneaux + accessoires + portes (MAD HT) | G22: =G9+G10+D20 -> 1877826.8

Sheet Bilan frigorifique
A1: Pré-dimensionnement de la puissance frigorifique (été) – à valider par un frigoriste
A2: Méthode : apports par parois + plafond + sol + renouvellement d'air + personnes + éclairage + équipements + produit, majorés, ramenés à la durée de fonctionnement des compresseurs. Zones « Réfrigérée = Non » : 0.
A4: Code | B4: Zone | C4: Réfrigérée | D4: T (°C) | E4: Surface (m²) | F4: Volume (m³) | G4: Parois (W) | H4: Plafond (W) | I4: Sol (W) | J4: Renouv. d'air (/24 h) | K4: Δh air (kJ/kg) | L4: Air (W) | M4: Personnes (nb) | N4: Chaleur / pers. (W) | O4: Présence (h/j) | P4: Personnes (W) | Q4: Éclairage (W/m²) | R4: Éclairage (h/j) | S4: Éclairage (W) | T4: Équipements (W) | U4: Produit (kg/j) | V4: T entrée produit (°C) | W4: cp produit (kJ/kg.K) | X4: Latente (kJ/kg) | Y4: Durée refroid. (h) | Z4: Produit (W) | AA4: Total apports (W) | AB4: Fonctionnement (h/j) | AC4: Puissance frigorifique (kW)
A5: =Zones!A5 -> Z1 | B5: =Zones!B5 -> Salle d'emballage | C5: =Zones!J5 -> Non | D5: =Zones!K5 -> 30 | E5: =Zones!E5 -> 289.1252 | F5: =Zones!H5 -> 1734.7512 | G5: =SUMIF(Parois!$B$5:$B$53,A5,Parois!$O$5:$O$53)+SUMIF(Parois!$C$5:$C$53,A5,Parois!$P$5:$P$53) -> 797.94 | H5: =IF(Zones!L5>0,Hypothèses!$B$4/(Zones!L5/1000),0)*Zones!N5*MAX(0,Hypothèses!$B$14-D5) -> 1060.1257 | I5: =IF(D5<0,Hypothèses!$B$6,Hypothèses!$B$7)*E5*MAX(0,Hypothèses!$B$15-D5) -> 0 | J5: 0 | K5: 0 | L5: =J5*F5*Hypothèses!$B$5*K5*1000/86400 -> 0 | M5: 0 | N5: 0 | O5: 0 | P5: =M5*N5*O5/24 -> 0 | Q5: 0 | R5: 0 | S5: =Q5*E5*R5/24 -> 0 | T5: 0 | U5: 0 | V5: 0 | W5: 0 | X5: 0 | Y5: 24 | Z5: =IF(Y5>0,U5*(W5*MAX(0,V5-D5)+X5)*1000/(Y5*3600),0) -> 0 | AA5: =G5+H5+I5+L5+P5+S5+T5+Z5 -> 1858.0657 | AB5: 18 | AC5: =IF(C5="Oui",AA5*(1+Hypothèses!$B$8)*24/AB5/1000,0) -> 0
A6: =Zones!A6 -> Z2 | B6: =Zones!B6 -> Zone de déchargement / refroidissement | C6: =Zones!J6 -> Non | D6: =Zones!K6 -> 30 | E6: =Zones!E6 -> 170.856 | F6: =Zones!H6 -> 1025.136 | G6: =SUMIF(Parois!$B$5:$B$53,A6,Parois!$O$5:$O$53)+SUMIF(Parois!$C$5:$C$53,A6,Parois!$P$5:$P$53) -> 368.731 | H6: =IF(Zones!L6>0,Hypothèses!$B$4/(Zones!L6/1000),0)*Zones!N6*MAX(0,Hypothèses!$B$14-D6) -> 626.472 | I6: =IF(D6<0,Hypothèses!$B$6,Hypothèses!$B$7)*E6*MAX(0,Hypothèses!$B$15-D6) -> 0 | J6: 0 | K6: 0 | L6: =J6*F6*Hypothèses!$B$5*K6*1000/86400 -> 0 | M6: 0 | N6: 0 | O6: 0 | P6: =M6*N6*O6/24 -> 0 | Q6: 0 | R6: 0 | S6: =Q6*E6*R6/24 -> 0 | T6: 0 | U6: 0 | V6: 0 | W6: 0 | X6: 0 | Y6: 24 | Z6: =IF(Y6>0,U6*(W6*MAX(0,V6-D6)+X6)*1000/(Y6*3600),0) -> 0 | AA6: =G6+H6+I6+L6+P6+S6+T6+Z6 -> 995.203 | AB6: 18 | AC6: =IF(C6="Oui",AA6*(1+Hypothèses!$B$8)*24/AB6/1000,0) -> 0
A7: =Zones!A7 -> Z3 | B7: =Zones!B7 -> Zone de stérilisation | C7: =Zones!J7 -> Non | D7: =Zones!K7 -> 35 | E7: =Zones!E7 -> 148.482 | F7: =Zones!H7 -> 890.892 | G7: =SUMIF(Parois!$B$5:$B$53,A7,Parois!$O$5:$O$53)+SUMIF(Parois!$C$5:$C$53,A7,Parois!$P$5:$P$53) -> 80.3 | H7: =IF(Zones!L7>0,Hypothèses!$B$4/(Zones!L7/1000),0)*Zones!N7*MAX(0,Hypothèses!$B$14-D7) -> 272.217 | I7: =IF(D7<0,Hypothèses!$B$6,Hypothèses!$B$7)*E7*MAX(0,Hypothèses!$B$15-D7) -> 0 | J7: 0 | K7: 0 | L7: =J7*F7*Hypothèses!$B$5*K7*1000/86400 -> 0 | M7: 0 | N7: 0 | O7: 0 | P7: =M7*N7*O7/24 -> 0 | Q7: 0 | R7: 0 | S7: =Q7*E7*R7/24 -> 0 | T7: 0 | U7: 0 | V7: 0 | W7: 0 | X7: 0 | Y7: 24 | Z7: =IF(Y7>0,U7*(W7*MAX(0,V7-D7)+X7)*1000/(Y7*3600),0) -> 0 | AA7: =G7+H7+I7+L7+P7+S7+T7+Z7 -> 352.517 | AB7: 18 | AC7: =IF(C7="Oui",AA7*(1+Hypothèses!$B$8)*24/AB7/1000,0) -> 0
A8: =Zones!A8 -> Z4 | B8: =Zones!B8 -> Zone de chargement paniers | C8: =Zones!J8 -> Non | D8: =Zones!K8 -> 30 | E8: =Zones!E8 -> 111.87 | F8: =Zones!H8 -> 671.22 | G8: =SUMIF(Parois!$B$5:$B$53,A8,Parois!$O$5:$O$53)+SUMIF(Parois!$C$5:$C$53,A8,Parois!$P$5:$P$53) -> 382.371 | H8: =IF(Zones!L8>0,Hypothèses!$B$4/(Zones!L8/1000),0)*Zones!N8*MAX(0,Hypothèses!$B$14-D8) -> 410.19 | I8: =IF(D8<0,Hypothèses!$B$6,Hypothèses!$B$7)*E8*MAX(0,Hypothèses!$B$15-D8) -> 0 | J8: 0 | K8: 0 | L8: =J8*F8*Hypothèses!$B$5*K8*1000/86400 -> 0 | M8: 0 | N8: 0 | O8: 0 | P8: =M8*N8*O8/24 -> 0 | Q8: 0 | R8: 0 | S8: =Q8*E8*R8/24 -> 0 | T8: 0 | U8: 0 | V8: 0 | W8: 0 | X8: 0 | Y8: 24 | Z8: =IF(Y8>0,U8*(W8*MAX(0,V8-D8)+X8)*1000/(Y8*3600),0) -> 0 | AA8: =G8+H8+I8+L8+P8+S8+T8+Z8 -> 792.561 | AB8: 18 | AC8: =IF(C8="Oui",AA8*(1+Hypothèses!$B$8)*24/AB8/1000,0) -> 0
A9: =Zones!A9 -> Z5 | B9: =Zones!B9 -> Zone de sertissage / conditionnement | C9: =Zones!J9 -> Non | D9: =Zones!K9 -> 30 | E9: =Zones!E9 -> 192.45 | F9: =Zones!H9 -> 1154.7 | G9: =SUMIF(Parois!$B$5:$B$53,A9,Parois!$O$5:$O$53)+SUMIF(Parois!$C$5:$C$53,A9,Parois!$P$5:$P$53) -> 183.44333 | H9: =IF(Zones!L9>0,Hypothèses!$B$4/(Zones!L9/1000),0)*Zones!N9*MAX(0,Hypothèses!$B$14-D9) -> 705.65 | I9: =IF(D9<0,Hypothèses!$B$6,Hypothèses!$B$7)*E9*MAX(0,Hypothèses!$B$15-D9) -> 0 | J9: 0 | K9: 0 | L9: =J9*F9*Hypothèses!$B$5*K9*1000/86400 -> 0 | M9: 0 | N9: 0 | O9: 0 | P9: =M9*N9*O9/24 -> 0 | Q9: 0 | R9: 0 | S9: =Q9*E9*R9/24 -> 0 | T9: 0 | U9: 0 | V9: 0 | W9: 0 | X9: 0 | Y9: 24 | Z9: =IF(Y9>0,U9*(W9*MAX(0,V9-D9)+X9)*1000/(Y9*3600),0) -> 0 | AA9: =G9+H9+I9+L9+P9+S9+T9+Z9 -> 889.09333 | AB9: 18 | AC9: =IF(C9="Oui",AA9*(1+Hypothèses!$B$8)*24/AB9/1000,0) -> 0
A10: =Zones!A10 -> Z6 | B10: =Zones!B10 -> Dépalettisation emballages vides | C10: =Zones!J10 -> Non | D10: =Zones!K10 -> 30 | E10: =Zones!E10 -> 25.5 | F10: =Zones!H10 -> 153 | G10: =SUMIF(Parois!$B$5:$B$53,A10,Parois!$O$5:$O$53)+SUMIF(Parois!$C$5:$C$53,A10,Parois!$P$5:$P$53) -> 0 | H10: =IF(Zones!L10>0,Hypothèses!$B$4/(Zones!L10/1000),0)*Zones!N10*MAX(0,Hypothèses!$B$14-D10) -> 93.5 | I10: =IF(D10<0,Hypothèses!$B$6,Hypothèses!$B$7)*E10*MAX(0,Hypothèses!$B$15-D10) -> 0 | J10: 0 | K10: 0 | L10: =J10*F10*Hypothèses!$B$5*K10*1000/86400 -> 0 | M10: 0 | N10: 0 | O10: 0 | P10: =M10*N10*O10/24 -> 0 | Q10: 0 | R10: 0 | S10: =Q10*E10*R10/24 -> 0 | T10: 0 | U10: 0 | V10: 0 | W10: 0 | X10: 0 | Y10: 24 | Z10: =IF(Y10>0,U10*(W10*MAX(0,V10-D10)+X10)*1000/(Y10*3600),0) -> 0 | AA10: =G10+H10+I10+L10+P10+S10+T10+Z10 -> 93.5 | AB10: 18 | AC10: =IF(C10="Oui",AA10*(1+Hypothèses!$B$8)*24/AB10/1000,0) -> 0
A11: =Zones!A11 -> Z7 | B11: =Zones!B11 -> Hygiène zone cuite | C11: =Zones!J11 -> Non | D11: =Zones!K11 -> 30 | E11: =Zones!E11 -> 8.4 | F11: =Zones!H11 -> 50.4 | G11: =SUMIF(Parois!$B$5:$B$53,A11,Parois!$O$5:$O$53)+SUMIF(Parois!$C$5:$C$53,A11,Parois!$P$5:$P$53) -> 0 | H11: =IF(Zones!L11>0,Hypothèses!$B$4/(Zones!L11/1000),0)*Zones!N11*MAX(0,Hypothèses!$B$14-D11) -> 30.8 | I11: =IF(D11<0,Hypothèses!$B$6,Hypothèses!$B$7)*E11*MAX(0,Hypothèses!$B$15-D11) -> 0 | J11: 0 | K11: 0 | L11: =J11*F11*Hypothèses!$B$5*K11*1000/86400 -> 0 | M11: 0 | N11: 0 | O11: 0 | P11: =M11*N11*O11/24 -> 0 | Q11: 0 | R11: 0 | S11: =Q11*E11*R11/24 -> 0 | T11: 0 | U11: 0 | V11: 0 | W11: 0 | X11: 0 | Y11: 24 | Z11: =IF(Y11>0,U11*(W11*MAX(0,V11-D11)+X11)*1000/(Y11*3600),0) -> 0 | AA11: =G11+H11+I11+L11+P11+S11+T11+Z11 -> 30.8 | AB11: 18 | AC11: =IF(C11="Oui",AA11*(1+Hypothèses!$B$8)*24/AB11/1000,0) -> 0
A12: =Zones!A12 -> Z8 | B12: =Zones!B12 -> Zone de cuisson / extrusion (ligne JBT) | C12: =Zones!J12 -> Non | D12: =Zones!K12 -> 35 | E12: =Zones!E12 -> 121.792 | F12: =Zones!H12 -> 730.752 | G12: =SUMIF(Parois!$B$5:$B$53,A12,Parois!$O$5:$O$53)+SUMIF(Parois!$C$5:$C$53,A12,Parois!$P$5:$P$53) -> 190.3 | H12: =IF(Zones!L12>0,Hypothèses!$B$4/(Zones!L12/1000),0)*Zones!N12*MAX(0,Hypothèses!$B$14-D12) -> 223.28533 | I12: =IF(D12<0,Hypothèses!$B$6,Hypothèses!$B$7)*E12*MAX(0,Hypothèses!$B$15-D12) -> 0 | J12: 0 | K12: 0 | L12: =J12*F12*Hypothèses!$B$5*K12*1000/86400 -> 0 | M12: 0 | N12: 0 | O12: 0 | P12: =M12*N12*O12/24 -> 0 | Q12: 0 | R12: 0 | S12: =Q12*E12*R12/24 -> 0 | T12: 0 | U12: 0 | V12: 0 | W12: 0 | X12: 0 | Y12: 24 | Z12: =IF(Y12>0,U12*(W12*MAX(0,V12-D12)+X12)*1000/(Y12*3600),0) -> 0 | AA12: =G12+H12+I12+L12+P12+S12+T12+Z12 -> 413.58533 | AB12: 18 | AC12: =IF(C12="Oui",AA12*(1+Hypothèses!$B$8)*24/AB12/1000,0) -> 0
A13: =Zones!A13 -> Z9 | B13: =Zones!B13 -> Salle de préparation viande | C13: =Zones!J13 -> Oui | D13: =Zones!K13 -> 10 | E13: =Zones!E13 -> 183.57 | F13: =Zones!H13 -> 1101.42 | G13: =SUMIF(Parois!$B$5:$B$53,A13,Parois!$O$5:$O$53)+SUMIF(Parois!$C$5:$C$53,A13,Parois!$P$5:$P$53) -> 2190.0175 | H13: =IF(Zones!L13>0,Hypothèses!$B$4/(Zones!L13/1000),0)*Zones!N13*MAX(0,Hypothèses!$B$14-D13) -> 1514.4525 | I13: =IF(D13<0,Hypothèses!$B$6,Hypothèses!$B$7)*E13*MAX(0,Hypothèses!$B$15-D13) -> 1101.42 | J13: 10 | K13: 45 | L13: =J13*F13*Hypothèses!$B$5*K13*1000/86400 -> 6883.875 | M13: 6 | N13: 210 | O13: 16 | P13: =M13*N13*O13/24 -> 840 | Q13: 10 | R13: 16 | S13: =Q13*E13*R13/24 -> 1223.8 | T13: 2000 | U13: 0 | V13: 10 | W13: 3.2 | X13: 0 | Y13: 24 | Z13: =IF(Y13>0,U13*(W13*MAX(0,V13-D13)+X13)*1000/(Y13*3600),0) -> 0 | AA13: =G13+H13+I13+L13+P13+S13+T13+Z13 -> 15753.565 | AB13: 18 | AC13: =IF(C13="Oui",AA13*(1+Hypothèses!$B$8)*24/AB13/1000,0) -> 25.205704
A14: =Zones!A14 -> Z10 | B14: =Zones!B14 -> Hygiène zone crue | C14: =Zones!J14 -> Non | D14: =Zones!K14 -> 20 | E14: =Zones!E14 -> 8.64 | F14: =Zones!H14 -> 51.84 | G14: =SUMIF(Parois!$B$5:$B$53,A14,Parois!$O$5:$O$53)+SUMIF(Parois!$C$5:$C$53,A14,Parois!$P$5:$P$53) -> 72.27 | H14: =IF(Zones!L14>0,Hypothèses!$B$4/(Zones!L14/1000),0)*Zones!N14*MAX(0,Hypothèses!$B$14-D14) -> 63.36 | I14: =IF(D14<0,Hypothèses!$B$6,Hypothèses!$B$7)*E14*MAX(0,Hypothèses!$B$15-D14) -> 0 | J14: 0 | K14: 0 | L14: =J14*F14*Hypothèses!$B$5*K14*1000/86400 -> 0 | M14: 0 | N14: 0 | O14: 0 | P14: =M14*N14*O14/24 -> 0 | Q14: 0 | R14: 0 | S14: =Q14*E14*R14/24 -> 0 | T14: 0 | U14: 0 | V14: 0 | W14: 0 | X14: 0 | Y14: 24 | Z14: =IF(Y14>0,U14*(W14*MAX(0,V14-D14)+X14)*1000/(Y14*3600),0) -> 0 | AA14: =G14+H14+I14+L14+P14+S14+T14+Z14 -> 135.63 | AB14: 18 | AC14: =IF(C14="Oui",AA14*(1+Hypothèses!$B$8)*24/AB14/1000,0) -> 0
A15: =Zones!A15 -> Z11 | B15: =Zones!B15 -> Couloir | C15: =Zones!J15 -> Non | D15: =Zones!K15 -> 30 | E15: =Zones!E15 -> 68.432 | F15: =Zones!H15 -> 410.592 | G15: =SUMIF(Parois!$B$5:$B$53,A15,Parois!$O$5:$O$53)+SUMIF(Parois!$C$5:$C$53,A15,Parois!$P$5:$P$53) -> 123.2 | H15: =IF(Zones!L15>0,Hypothèses!$B$4/(Zones!L15/1000),0)*Zones!N15*MAX(0,Hypothèses!$B$14-D15) -> 250.91733 | I15: =IF(D15<0,Hypothèses!$B$6,Hypothèses!$B$7)*E15*MAX(0,Hypothèses!$B$15-D15) -> 0 | J15: 0 | K15: 0 | L15: =J15*F15*Hypothèses!$B$5*K15*1000/86400 -> 0 | M15: 0 | N15: 0 | O15: 0 | P15: =M15*N15*O15/24 -> 0 | Q15: 0 | R15: 0 | S15: =Q15*E15*R15/24 -> 0 | T15: 0 | U15: 0 | V15: 0 | W15: 0 | X15: 0 | Y15: 24 | Z15: =IF(Y15>0,U15*(W15*MAX(0,V15-D15)+X15)*1000/(Y15*3600),0) -> 0 | AA15: =G15+H15+I15+L15+P15+S15+T15+Z15 -> 374.11733 | AB15: 18 | AC15: =IF(C15="Oui",AA15*(1+Hypothèses!$B$8)*24/AB15/1000,0) -> 0
A16: =Zones!A16 -> Z12 | B16: =Zones!B16 -> SAS quai réfrigéré | C16: =Zones!J16 -> Oui | D16: =Zones!K16 -> 5 | E16: =Zones!E16 -> 44.06 | F16: =Zones!H16 -> 264.36 | G16: =SUMIF(Parois!$B$5:$B$53,A16,Parois!$O$5:$O$53)+SUMIF(Parois!$C$5:$C$53,A16,Parois!$P$5:$P$53) -> 560.043 | H16: =IF(Zones!L16>0,Hypothèses!$B$4/(Zones!L16/1000),0)*Zones!N16*MAX(0,Hypothèses!$B$14-D16) -> 339.262 | I16: =IF(D16<0,Hypothèses!$B$6,Hypothèses!$B$7)*E16*MAX(0,Hypothèses!$B$15-D16) -> 396.54 | J16: 20 | K16: 60 | L16: =J16*F16*Hypothèses!$B$5*K16*1000/86400 -> 4406 | M16: 1 | N16: 270 | O16: 4 | P16: =M16*N16*O16/24 -> 45 | Q16: 8 | R16: 4 | S16: =Q16*E16*R16/24 -> 58.746667 | T16: 0 | U16: 0 | V16: 5 | W16: 3.2 | X16: 0 | Y16: 24 | Z16: =IF(Y16>0,U16*(W16*MAX(0,V16-D16)+X16)*1000/(Y16*3600),0) -> 0 | AA16: =G16+H16+I16+L16+P16+S16+T16+Z16 -> 5805.5917 | AB16: 18 | AC16: =IF(C16="Oui",AA16*(1+Hypothèses!$B$8)*24/AB16/1000,0) -> 9.2889467
... A19: =Zones!A19 -> Z15 | B19: =Zones!B19 -> Circulation Unité Humide (hors SAS) | C19: =Zones!J19 -> Non | D19: =Zones!K19 -> 30 | E19: =Zones!E19 -> 192.8 | F19: =Zones!H19 -> 1156.8 | G19: =SUMIF(Parois!$B$5:$B$53,A19,Parois!$O$5:$O$53)+SUMIF(Parois!$C$5:$C$53,A19,Parois!$P$5:$P$53) -> 76.45 | H19: =IF(Zones!L19>0,Hypothèses!$B$4/(Zones!L19/1000),0)*Zones!N19*MAX(0,Hypothèses!$B$14-D19) -> 0 | I19: =IF(D19<0,Hypothèses!$B$6,Hypothèses!$B$7)*E19*MAX(0,Hypothèses!$B$15-D19) -> 0 | J19: 0 | K19: 0 | L19: =J19*F19*Hypothèses!$B$5*K19*1000/86400 -> 0 | M19: 0 | N19: 0 | O19: 0 | P19: =M19*N19*O19/24 -> 0 | Q19: 0 | R19: 0 | S19: =Q19*E19*R19/24 -> 0 | T19: 0 | U19: 0 | V19: 0 | W19: 0 | X19: 0 | Y19: 24 | Z19: =IF(Y19>0,U19*(W19*MAX(0,V19-D19)+X19)*1000/(Y19*3600),0) -> 0 | AA19: =G19+H19+I19+L19+P19+S19+T19+Z19 -> 76.45 | AB19: 18 | AC19: =IF(C19="Oui",AA19*(1+Hypothèses!$B$8)*24/AB19/1000,0) -> 0
B20: TOTAL zones réfrigérées | AC20: =SUM(AC5:AC19) -> 63.04214
B22: Sources et hypothèses :
B23: • Chaleur dégagée par personne selon la température : ASHRAE Handbook – Refrigeration, chap. « Refrigerated-Facility Loads » (≈ 210 W à +10 °C, 270 W à 0 °C, 390 W à −20 °C).
B24: • Δh air : air extérieur 35 °C / 40 % HR (h ≈ 72 kJ/kg) ; −20 °C : h ≈ −18 ; +2 °C / 85 % : h ≈ 11 ; +10 °C / 80 % : h ≈ 26 kJ/kg.
B25: • Renouvellements d'air, personnes, éclairage, équipements, produit : valeurs d'EXEMPLE à remplacer par les données d'exploitation (tonnages journaliers, températures d'arrivée, temps de refroidissement).
B26: • Produit Z13 : 10 t/j de viande congelée arrivant à −12 °C (cp 1,7 kJ/kg.K) ; Z14 : 5 t/j arrivant à +7 °C (cp 3,2). Z12 (SAS quai) : 20 renouvellements/j pour les ouvertures de la porte de quai (hypothèse). Mettre la chaleur latente (≈ 230 kJ/kg) si la chambre doit congeler du produit frais.
B27: • Résultat = puissance frigorifique utile à l'évaporateur ; la puissance électrique absorbée dépend du COP de l'installation.

Sheet Équipements
A1: Équipements process – encombrements et utilités (d'après les documents fournisseurs)
A2: Valeurs saisies telles qu'indiquées par les fournisseurs (mm, kg, kW). Vide = non communiqué. « est. » = estimé sur plan.
A4: Zone | B4: Équipement | C4: Qté | D4: Longueur (mm) | E4: Largeur (mm) | F4: Hauteur (mm) | G4: Poids unit. (kg) | H4: Puissance unit. (kW) | I4: Puissance totale (kW) | J4: Air comprimé | K4: Eau / vapeur | L4: Bruit (dB) | M4: Remarques | N4: Source
A5: Z9 | B5: Karl Schnell – mélangeur 1500 + trémie 2000 + émulsionneur FD225 DK | C5: 1 | D5: 4834 | E5: 5247 | F5: 3857 | I5: =IF(H5="","",C5*H5) | M5: Groupe complet avec plateforme et élévateur (hauteur maxi 4 903 au basculement) | N5: Karl Schnell 24_001-G (18.03.2025)
A6: Z9 | B6: Karl Schnell – hachoir automatique AG-K280 T470 + élévateur + chariot | C6: 1 | D6: 1858 | E6: 5953 | F6: 3422 | I6: =IF(H6="","",C6*H6) | M6: Zone de maintenance devant la machine | N6: Karl Schnell 24_001-G
A7: Z9 | B7: Karl Schnell – armoire électrique | C7: 1 | D7: 2400 | E7: 500 | F7: 2100 | I7: =IF(H7="","",C7*H7) | N7: Karl Schnell 24_001-G
A8: Z9 | B8: JBT FTNON – trémie émulsion 1000 L | C8: 1 | D8: 1800 | E8: 1800 | F8: 1850 | I8: =IF(H8="","",C8*H8) | M8: Ø 1 800 | N8: JBT 05X0292.000 rev. A
A9: Z9/Z8 | B9: JBT FTNON – extrudeuse 800 + tunnel vapeur 800×8000 | C9: 1 | D9: 12547 | E9: 3056 | F9: 2719 | I9: =IF(H9="","",C9*H9) | K9: Vapeur | M9: Largeur capot ouvert 3 056 ; 2 extractions Ø356 ; traversée étanche de la paroi Z9/Z8 | N9: JBT 05X0292.000 rev. A
A10: Z8 | B10: JBT FTNON – convoyeur de refroidissement 800×4000 + découpe | C10: 1 | D10: 6000 | E10: 2500 | F10: 1340 | I10: =IF(H10="","",C10*H10) | M10: Longueur est. (convoyeur 4 000 + découpe ~2 000) | N10: JBT 05X0292.000 (est. à l'échelle)
A11: Z5 | B11: Waldner Dosomat 12.6 – 13308 (barquettes alu) | C11: 1 | D11: 5350 | E11: 2880 | F11: 2466 | H11: 20 | I11: =IF(H11="","",C11*H11) -> 20 | J11: 600 l/min à 6 bar, 1/2" | K11: Eau 60 l/h | M11: Encombrement porte armoire comprise ; dimensions d'introduction 3 600 × 2 950 × 2 500 | N11: Waldner 100594254 (23.07.2026)
A12: Z5 | B12: SOMME PE-6 MIX – sertisseuse boîtes Ø73–99 | C12: 1 | D12: 2355 | E12: 1200 | F12: 2015 | G12: 1700 | H12: 5 | I12: =IF(H12="","",C12*H12) -> 5 | J12: 3–4 bar ; 80 l/h à 6 bar (à vérifier) | L12: 82.9 | M12: Entrée/sortie boîtes à 1 000 mm ; 50–200 b/min recommandé, 250 maxi (demande 220) | N12: Somme offre 42400084/00 (13.05.2024)
A13: Z5 | B13: Zilli & Bellini – remplisseuse à poches TB (12 ou 16 télescopes, à confirmer) | C13: 1 | D13: 5300 | E13: 2500 | H13: 8 | I13: =IF(H13="","",C13*H13) -> 8 | J13: 400 Nl/min à 6 bar, 1/2" G | K13: Exclus (vapeur, eau, CIP) | M13: Carter 2 630 × 2 500 ; portes ouvertes 4 930 × 4 350 ; convoyeur boîtes à 1 100 ± 50 (sertisseuse à 1 000) ; 80 b/min (400 g), 30 b/min (1 250 g) ; armoire séparée à 2–3 m ; tension 50 Hz à confirmer (offre : 60 Hz) | N13: Zilli & Bellini O24/450 + LAY00537 (01/08/2024)
A14: Z4 | B14: Chargeur de paniers (réserve) | C14: 2 | D14: 1800 | E14: 1900 | I14: =IF(H14="","",C14*H14) | M14: Un par ligne (Dosomat, boîtes) ; navette de transfert devant les 6 portes sud | N14: —
A15: Z3 | B15: Steriflow – stérilisateur 1300 (LU 5 530), version double porte à confirmer | C15: 6 | D15: 7225 | E15: 1650 | F15: 2052 | G15: 10350 | I15: =IF(H15="","",C15*H15) | J15: AAC 1"1/2, SAC 1" | K15: Vapeur DN50, eau froide DN50 | M15: Largeur est. ~1 650 (1 510 démonté) ; poids plein d'eau 10 350 daN ; le devis actuel est à porte simple : demander la version traversante (2 portes) | N15: Steriflow SC-NG2-1361 rév. B
A16: Z2 | B16: Déchargeur de paniers (réserve) | C16: 1 | D16: 1900 | E16: 1800 | I16: =IF(H16="","",C16*H16) | M16: Sortie vers l'emballage par la porte est | N16: —
B17: TOTAL puissance connue (kW) | I17: =SUM(I5:I16) -> 33
B18: Charge totale connue (kg, autoclaves pleins d'eau) | G18: =SUMPRODUCT(C5:C16,G5:G16) -> 63800
